Workbook

Sheet 1. Trade-Off-QA
A1: Atributos propuestos por usuario | Q1: Atributos Promediados entre usuario y Arquitectos
A2: Atributos de Calidad | B2: Prioridad | C2: <----Prioridad----> | Q2: Atributos de Calidad | R2: Prioridad | S2: <----Prioridad---->
C3: 1 | D3: 2 | E3: 3 | F3: 4 | G3: 5 | H3: 6 | I3: 7 | J3: 8 | K3: 9 | L3: 10 | M3: 11 | N3: 12 | O3: 13 | S3: 1 | T3: 2 | U3: 3 | V3: 4 | W3: 5 | X3: 6 | Y3: 7 | Z3: 8 | AA3: 9 | AB3: 10 | AC3: 11 | AD3: 12 | AE3: 13
A4: Confiabilidad | B4: 1 | Q4: Confiabilidad | R4: 1
A5: Experiencia de Usuario | B5: 2 | Q5: Capacidad para ser Auditado | R5: 2
A6: Disponibilidad | B6: 3 | Q6: Rendimiento | R6: 3
A7: Seguridad | B7: 4 | Q7: Seguridad | R7: 4
A8: Rendimiento | B8: 5 | Q8: Experiencia de Usuario | R8: 5
A9: Capacidad para ser Soportado | B9: 6 | Q9: Disponibilidad | R9: 6
A10: Capacidad para ser Administrado | B10: 7 | Q10: Escalabilidad | R10: 7
A11: Portabilidad | B11: 8 | Q11: Capacidad para ser Administrado | R11: 8
A12: Capacidad | B12: 9 | Q12: Portabilidad | R12: 9
A13: Accesibilidad | B13: 10 | Q13: Capacidad | R13: 10
A14: Capacidad para ser Auditado | B14: 11 | Q14: Capacidad para ser Soportado | R14: 11
A15: Escalabilidad | B15: 12 | Q15: Interoperatividad | R15: 12
A16: Interoperatividad | B16: 13 | Q16: Accesibilidad | R16: 13
A18: Atributos Propuestos por Arquitectos
A19: Atributos de Calidad | B19: Prioridad | C19: <----Prioridad---->
C20: 1 | D20: 2 | E20: 3 | F20: 4 | G20: 5 | H20: 6 | I20: 7 | J20: 8 | K20: 9 | L20: 10 | M20: 11 | N20: 12 | O20: 13
A21: Confiabilidad | B21: 1
A22: Disponibilidad | B22: 2
A23: Capacidad | B23: 3
A24: Rendimiento | B24: 4
A25: Capacidad para ser Auditado | B25: 5
A26: Capacidad para ser Administrado | B26: 6
A27: Interoperatividad | B27: 7
A28: Experiencia de Usuario | B28: 8
A29: Seguridad | B29: 9
A30: Portabilidad | B30: 10
A31: Capacidad para ser Soportado | B31: 11
A32: Accesibilidad | B32: 12
A33: Escalabilidad | B33: 13

Sheet 2. Priorización-QA
A1: Atributos de calidad | B1: <---Actores---->
B2: Supervisor de Campo | C2: Gerente de producción | D2: Administrador del sistema | E2: Puntuación total | F2: Porcentaje
A3: Confiabilidad | B3: 1 | C3: 1 | D3: 1 | E3: =SUM(B3:D3) -> 3 | F3: =E3/E$16 -> 0.010989011
A4: Disponibilidad | B4: 2 | C4: 2 | D4: 7 | E4: =SUM(B4:D4) -> 11 | F4: =E4/E$16 -> 0.04029304
A5: Rendimiento | B5: 3 | C5: 5 | D5: 9 | E5: =SUM(B5:D5) -> 17 | F5: =E5/E$16 -> 0.062271062
A6: Capacidad para ser Auditado | B6: 9 | C6: 4 | D6: 4 | E6: =SUM(B6:D6) -> 17 | F6: =E6/E$16 -> 0.062271062
A7: Capacidad | B7: 11 | C7: 3 | D7: 5 | E7: =SUM(B7:D7) -> 19 | F7: =E7/E$16 -> 0.06959707
A8: Capacidad para ser Administrado | B8: 13 | C8: 7 | D8: 3 | E8: =SUM(B8:D8) -> 23 | F8: =E8/E$16 -> 0.084249084
A9: Experiencia de Usuario | B9: 6 | C9: 6 | D9: 12 | E9: =SUM(B9:D9) -> 24 | F9: =E9/E$16 -> 0.087912088
A10: Seguridad | B10: 10 | C10: 8 | D10: 6 | E10: =SUM(B10:D10) -> 24 | F10: =E10/E$16 -> 0.087912088
A11: Interoperatividad | B11: 5 | C11: 10 | D11: 10 | E11: =SUM(B11:D11) -> 25 | F11: =E11/E$16 -> 0.091575092
A12: Escalabilidad | B12: 8 | C12: 9 | D12: 8 | E12: =SUM(B12:D12) -> 25 | F12: =E12/E$16 -> 0.091575092
A13: Capacidad para ser Soportado | B13: 12 | C13: 13 | D13: 2 | E13: =SUM(B13:D13) -> 27 | F13: =E13/E$16 -> 0.098901099
A14: Portabilidad | B14: 4 | C14: 11 | D14: 13 | E14: =SUM(B14:D14) -> 28 | F14: =E14/E$16 -> 0.1025641
A15: Accesibilidad | B15: 7 | C15: 12 | D15: 11 | E15: =SUM(B15:D15) -> 30 | F15: =E15/E$16 -> 0.10989011
B16: =SUM(B3:B15) -> 91 | C16: =SUM(C3:C15) -> 91 | D16: =SUM(D3:D15) -> 91 | E16: =SUM(E3:E15) -> 273 | F16: =SUM(F3:F15) -> 1
E18: |

Sheet 3. Caracterización
A1: Atributo de calidad | B1: Pregunta | C1: Respuesta Juan | D1: Respuesta Jeronimo | E1: Respuesta Cliente | F1: Nota | G1: Tomador de datos | H1: Produccion | I1: Administrador | J1: Puntaje Total | K1: Seleccionada (Top 65)
A2: Confiabilidad | B2: ¿Se necesita verificar que la información sea correcta de manera individual con cada dato tomado? | C2: NO | D2: NO | E2: SI | J2: =SUM(G2:I2) -> 0
A3: Confiabilidad | B3: ¿Se necesita verificar que la información sea correcta de manera que se agrupe la información por variedad? | C3: SI | D3: SI | E3: SI | J3: =SUM(G3:I3) -> 0
A4: Confiabilidad | B4: ¿Se necesita verificar que la información sea correcta de manera que se agrupe la información por sección de la cama? | C4: SI | D4: SI | E4: NO | J4: =SUM(G4:I4) -> 0
A5: Confiabilidad | B5: ¿Se necesita verificar que la información sea correcta de manera que se agrupe la información por cama? | C5: SI | D5: SI | E5: SI | J5: =SUM(G5:I5) -> 0
A6: Confiabilidad | B6: ¿Se necesita verificar que la información sea correcta de manera que se agrupe la información por bloque? | C6: NO | D6: SI | E6: SI | F6: NO TAN IMPORTANTE | J6: =SUM(G6:I6) -> 0
A7: Confiabilidad | B7: ¿Se necesita verificar que la información sea correcta de manera que se agrupe la información por finca y por jornada completa? | C7: SI | D7: SI | E7: SI | H7: 2 | J7: =SUM(G7:I7) -> 2 | K7: SI
A8: Confiabilidad | B8: ¿Se necesita una confirmación final que muestre todo lo capturado antes de darlo por guardado? | C8: SI | D8: SI | E8: NO | J8: =SUM(G8:I8) -> 0
A9: Confiabilidad | B9: ¿Se necesita que el sistema impida cerrar la captura de una cama si quedaron campos sin diligenciar? | C9: SI | D9: SI | E9: NO | F9: HAY CAMPOS QUE NO SON CONCORDANTES CON OTROS | J9: =SUM(G9:I9) -> 0
A10: Confiabilidad | B10: ¿Se necesita que el sistema permita guardar una captura incompleta y marcarla como pendiente? | C10: SI | D10: SI | E10: SI | H10: 1 | J10: =SUM(G10:I10) -> 1 | K10: SI
A11: Confiabilidad | B11: ¿Se necesita que el sistema rechace un dato cuando está fuera del rango posible (por ejemplo, más tallos que plantas sembradas)? | C11: SI | D11: SI | E11: SI | G11: 3 | H11: 3 | J11: =SUM(G11:I11) -> 6 | K11: SI
A12: Confiabilidad | B12: ¿Se necesita que el sistema advierta, sin bloquear, cuando un dato se aleja mucho de lo que se ha capturado históricamente en esa misma cama? | C12: NO | D12: NO | E12: SI | J12: =SUM(G12:I12) -> 0
A13: Confiabilidad | B13: ¿Se necesita que el sistema muestre siempre el motivo por el cual rechazó un dato? | C13: SI | D13: SI | E13: SI | H13: 1 | J13: =SUM(G13:I13) -> 1 | K13: SI
A14: Confiabilidad | B14: ¿Se necesita que los rangos y las reglas de validación se puedan cambiar sin depender de una nueva versión de la aplicación? | C14: SI | D14: SI | E14: SI | H14: 3 | I14: 1 | J14: =SUM(G14:I14) -> 4 | K14: SI
A15: Confiabilidad | B15: ¿Se necesita que las reglas de validación funcionen igual estando sin conexión que estando conectado? | C15: SI | D15: SI | E15: SI | G15: 1 | J15: =SUM(G15:I15) -> 1 | K15: SI
A16: Confiabilidad | B16: ¿Se necesita que el sistema avise cuando se intenta capturar dos veces la misma cama el mismo día? | C16: SI | D16: SI | E16: SI | G16: 2 | J16: =SUM(G16:I16) -> 2 | K16: SI
A17: Confiabilidad | B17: ¿Se necesita que el sistema avise cuando una cama lleva más días de lo normal sin ser capturada? | C17: SI | D17: SI | E17: SI | J17: =SUM(G17:I17) -> 0
A18: Confiabilidad | B18: ¿Se necesita que el sistema impida registrar una labor sobre una cama que ya fue erradicada? | C18: NO | D18: NO | E18: NO | F18: DEPENDE DEL TIPO DE INGRESO DE DATO | J18: =SUM(G18:I18) -> 0
A19: Confiabilidad | B19: ¿Se necesita que el sistema bloquee la captura cuando detecta que la fecha y la hora del dispositivo fueron alteradas? | C19: SI | D19: SI | E19: SI | G19: 1 | I19: 2 | J19: =SUM(G19:I19) -> 3 | K19: SI
A20: Confiabilidad | B20: ¿Se necesita realizar la captura de datos de manera progresiva y guiada pantalla por pantalla (primero se selecciona bloque, luego cama, luego se captura lote y fecha de siembra, después las variedades plantadas)? | C20: NO | D20: NO | E20: NO | J20: =SUM(G20:I20) -> 0
A21: Confiabilidad | B21: ¿Se necesita realizar la captura de datos con una plantilla predefinida que use una estructura similar a las plantillas de papel utilizadas previamente? | C21: SI | D21: SI | E21: SI | G21: 1 | J21: =SUM(G21:I21) -> 1 | K21: NO
A22: Confiabilidad | B22: ¿Se necesita que la estructura de captura sea siempre la misma para todos los bloques de la finca? | C22: NO | D22: NO | E22: SI | J22: =SUM(G22:I22) -> 0
A23: Confiabilidad | B23: ¿Se necesita que la estructura de captura pueda cambiar según la variedad que se esté trabajando? | C23: SI | D23: SI | E23: NO | F23: PUEDEN HABER DATOS EN BLANCO | J23: =SUM(G23:I23) -> 0
A24: Confiabilidad | B24: ¿Se necesita que el sistema proponga automáticamente el valor capturado la última vez para esa misma cama? | C24: NO | D24: NO | E24: NO | J24: =SUM(G24:I24) -> 0
A25: Confiabilidad | B25: ¿Se necesita que el orden de captura siga el recorrido físico que se hace dentro del bloque? | C25: NO | D25: NO | E25: NO | J25: =SUM(G25:I25) -> 0
A26: Confiabilidad | B26: ¿Se necesita que el sistema indique en todo momento cuántas camas faltan por capturar en la jornada? | C26: NO | D26: NO | E26: NO | J26: =SUM(G26:I26) -> 0
A27: Confiabilidad | B27: ¿Se necesita poder corregir un dato ya capturado antes de que se sincronice? | C27: SI | D27: SI | E27: SI | G27: 4 | J27: =SUM(G27:I27) -> 4 | K27: SI
A28: Confiabilidad | B28: ¿Se necesita poder corregir un dato después de que se sincronizó? | C28: SI | D28: SI | E28: SI | I28: 1 | J28: =SUM(G28:I28) -> 1 | K28: SI
A29: Confiabilidad | B29: ¿Se necesita que al corregir un dato se conserve visible el valor original? | C29: NO | D29: NO | E29: NO | J29: =SUM(G29:I29) -> 0
A30: Confiabilidad | B30: ¿Se necesita que toda corrección exija escribir un motivo? | C30: NO | D30: NO | E30: NO | J30: =SUM(G30:I30) -> 0
A31: Confiabilidad | B31: ¿Se necesita que exista una fecha a partir de la cual la información ya no se pueda corregir? | C31: NO | D31: NO | E31: NO | J31: =SUM(G31:I31) -> 0
A32: Confiabilidad | B32: ¿Se necesita que, cuando dos capturas de la misma cama entran en conflicto, el sistema resuelva solo tomando la más reciente? | C32: NO | D32: NO | E32: NO | J32: =SUM(G32:I32) -> 0
A33: Confiabilidad | B33: ¿Se necesita que, cuando dos capturas de la misma cama entran en conflicto, el sistema deje ambas y pida que una persona decida? | C33: SI | D33: SI | E33: NO | F33: NO DEJA INGRESAR EL ULTIMO REGISTRO | J33: =SUM(G33:I33) -> 0
A34: Confiabilidad | B34: ¿Se necesita que quien capturó el dato se entere cuando su captura fue descartada o modificada por un conflicto? | C34: NO | D34: NO | E34: SI | J34: =SUM(G34:I34) -> 0
A35: Confiabilidad | B35: ¿Se necesita saber, sobre cada proyección, con qué datos y con qué parámetros fue calculada? | C35: SI | D35: SI | E35: SI | H35: 4 | J35: =SUM(G35:I35) -> 4 | K35: SI
A36: Confiabilidad | B36: ¿Se necesita que una misma proyección, recalculada meses después, dé exactamente el mismo resultado? | C36: NO | D36: NO | E36: SI | F36: SI NO SE MODIFICA SI | J36: =SUM(G36:I36) -> 0
A37: Confiabilidad | B37: ¿Se necesita que el sistema muestre cuánto se desvió la proyección anterior frente a lo que realmente se cortó? | C37: SI | D37: SI | E37: SI | F37: SOBRE LA MISMA PROYECCION | H37: 4 | J37: =SUM(G37:I37) -> 4 | K37: SI
A38: Confiabilidad | B38: ¿Se necesita que el sistema muestre un indicador del porcentaje de datos con error o pendientes de verificación? | C38: NO | D38: NO | E38: NO | J38: =SUM(G38:I38) -> 0
A39: Confiabilidad | B39: ¿Se necesita fijar una meta explícita de porcentaje máximo de error aceptable en la información capturada? | C39: SI | D39: NO | E39: NO | F39: NO PUEDE HABER ERRORES | J39: =SUM(G39:I39) -> 0
A40: Confiabilidad | B40: ¿Se necesita que el sistema distinga la información verificada de la que todavía no lo ha sido? | C40: NO | D40: NO | E40: NO | J40: =SUM(G40:I40) -> 0
...

Sheet 4, Lluvia-de-Escenarios

Sheet Top 65 - Priorizadas
A1: Rank | B1: Atributo de calidad | C1: Pregunta | D1: Tomador de datos | E1: Producción | F1: Administrador | G1: Puntaje Total
A2: 1 | B2: ='3. Caracterización'!A44 -> Confiabilidad | C2: ='3. Caracterización'!B44 -> ¿Se necesita que no se pierda ningún dato capturado bajo ninguna circunstancia? | D2: ='3. Caracterización'!G44 -> 5 | E2: ='3. Caracterización'!H44 -> 5 | F2: ='3. Caracterización'!I44 -> 0 | G2: =SUM(D2:F2) -> 10
A3: 2 | B3: ='3. Caracterización'!A11 -> Confiabilidad | C3: ='3. Caracterización'!B11 -> ¿Se necesita que el sistema rechace un dato cuando está fuera del rango posible (por ejemplo, más tallos que plantas sembradas)? | D3: ='3. Caracterización'!G11 -> 3 | E3: ='3. Caracterización'!H11 -> 3 | F3: ='3. Caracterización'!I11 -> 0 | G3: =SUM(D3:F3) -> 6
A4: 3 | B4: ='3. Caracterización'!A49 -> Confiabilidad | C4: ='3. Caracterización'!B49 -> ¿Se necesita que el sistema haga copias de respaldo de manera automática, sin que nadie lo solicite? | D4: ='3. Caracterización'!G49 -> 0 | E4: ='3. Caracterización'!H49 -> 0 | F4: ='3. Caracterización'!I49 -> 5 | G4: =SUM(D4:F4) -> 5
A5: 4 | B5: ='3. Caracterización'!A59 -> Disponibilidad | C5: ='3. Caracterización'!B59 -> ¿Se necesita capturar información en el área de cultivo sin ninguna conexión de datos? | D5: ='3. Caracterización'!G59 -> 5 | E5: ='3. Caracterización'!H59 -> 0 | F5: ='3. Caracterización'!I59 -> 0 | G5: =SUM(D5:F5) -> 5
A6: 5 | B6: ='3. Caracterización'!A95 -> Rendimiento | C6: ='3. Caracterización'!B95 -> ¿Se necesita que la proyección se recalcule en el momento en que llega información nueva? | D6: ='3. Caracterización'!G95 -> 0 | E6: ='3. Caracterización'!H95 -> 5 | F6: ='3. Caracterización'!I95 -> 0 | G6: =SUM(D6:F6) -> 5
A7: 6 | B7: ='3. Caracterización'!A162 -> Capacidad para ser Administrado | C7: ='3. Caracterización'!B162 -> ¿Se necesita que quien administra el sistema en la finca no pueda modificar la información de producción? | D7: ='3. Caracterización'!G162 -> 0 | E7: ='3. Caracterización'!H162 -> 0 | F7: ='3. Caracterización'!I162 -> 5 | G7: =SUM(D7:F7) -> 5
A8: 7 | B8: ='3. Caracterización'!A14 -> Confiabilidad | C8: ='3. Caracterización'!B14 -> ¿Se necesita que los rangos y las reglas de validación se puedan cambiar sin depender de una nueva versión de la aplicación? | D8: ='3. Caracterización'!G14 -> 0 | E8: ='3. Caracterización'!H14 -> 3 | F8: ='3. Caracterización'!I14 -> 1 | G8: =SUM(D8:F8) -> 4
A9: 8 | B9: ='3. Caracterización'!A27 -> Confiabilidad | C9: ='3. Caracterización'!B27 -> ¿Se necesita poder corregir un dato ya capturado antes de que se sincronice? | D9: ='3. Caracterización'!G27 -> 4 | E9: ='3. Caracterización'!H27 -> 0 | F9: ='3. Caracterización'!I27 -> 0 | G9: =SUM(D9:F9) -> 4
A10: 9 | B10: ='3. Caracterización'!A35 -> Confiabilidad | C10: ='3. Caracterización'!B35 -> ¿Se necesita saber, sobre cada proyección, con qué datos y con qué parámetros fue calculada? | D10: ='3. Caracterización'!G35 -> 0 | E10: ='3. Caracterización'!H35 -> 4 | F10: ='3. Caracterización'!I35 -> 0 | G10: =SUM(D10:F10) -> 4
A11: 10 | B11: ='3. Caracterización'!A37 -> Confiabilidad | C11: ='3. Caracterización'!B37 -> ¿Se necesita que el sistema muestre cuánto se desvió la proyección anterior frente a lo que realmente se cortó? | D11: ='3. Caracterización'!G37 -> 0 | E11: ='3. Caracterización'!H37 -> 4 | F11: ='3. Caracterización'!I37 -> 0 | G11: =SUM(D11:F11) -> 4
A12: 11 | B12: ='3. Caracterización'!A45 -> Confiabilidad | C12: ='3. Caracterización'!B45 -> ¿Se necesita que la información se conserve cuando el dispositivo se apaga por batería agotada a mitad de una captura? | D12: ='3. Caracterización'!G45 -> 4 | E12: ='3. Caracterización'!H45 -> 0 | F12: ='3. Caracterización'!I45 -> 0 | G12: =SUM(D12:F12) -> 4
A13: 12 | B13: ='3. Caracterización'!A107 -> Capacidad para ser Auditado | C13: ='3. Caracterización'!B107 -> ¿Se necesita poder ver la historia completa de una cama desde la siembra hasta la erradicación? | D13: ='3. Caracterización'!G107 -> 0 | E13: ='3. Caracterización'!H107 -> 4 | F13: ='3. Caracterización'!I107 -> 0 | G13: =SUM(D13:F13) -> 4
A14: 13 | B14: ='3. Caracterización'!A147 -> Capacidad para ser Administrado | C14: ='3. Caracterización'!B147 -> ¿Se necesita poder crear y dar de baja usuarios sin solicitarlo a quien desarrolló el sistema? | D14: ='3. Caracterización'!G147 -> 0 | E14: ='3. Caracterización'!H147 -> 0 | F14: ='3. Caracterización'!I147 -> 4 | G14: =SUM(D14:F14) -> 4
A15: 14 | B15: ='3. Caracterización'!A161 -> Capacidad para ser Administrado | C15: ='3. Caracterización'!B161 -> ¿Se necesita que la administración del sistema se pueda hacer desde un computador de la finca, sin herramientas técnicas especiales? | D15: ='3. Caracterización'!G161 -> 0 | E15: ='3. Caracterización'!H161 -> 0 | F15: ='3. Caracterización'!I161 -> 4 | G15: =SUM(D15:F15) -> 4
A16: 15 | B16: ='3. Caracterización'!A165 -> Experiencia de Usuario | C16: ='3. Caracterización'!B165 -> ¿Se necesita que la pantalla sea legible bajo el sol directo? | D16: ='3. Caracterización'!G165 -> 4 | E16: ='3. Caracterización'!H165 -> 0 | F16: ='3. Caracterización'!I165 -> 0 | G16: =SUM(D16:F16) -> 4
A17: 16 | B17: ='3. Caracterización'!A248 -> Portabilidad | C17: ='3. Caracterización'!B248 -> ¿Se necesita que el sistema pueda instalarse en servidores de la propia empresa y no solo en la nube? | D17: ='3. Caracterización'!G248 -> 0 | E17: ='3. Caracterización'!H248 -> 0 | F17: ='3. Caracterización'!I248 -> 4 | G17: =SUM(D17:F17) -> 4
A18: 17 | B18: ='3. Caracterización'!A19 -> Confiabilidad | C18: ='3. Caracterización'!B19 -> ¿Se necesita que el sistema bloquee la captura cuando detecta que la fecha y la hora del dispositivo fueron alteradas? | D18: ='3. Caracterización'!G19 -> 1 | E18: ='3. Caracterización'!H19 -> 0 | F18: ='3. Caracterización'!I19 -> 2 | G18: =SUM(D18:F18) -> 3
A19: 18 | B19: ='3. Caracterización'!A46 -> Confiabilidad | C19: ='3. Caracterización'!B46 -> ¿Se necesita que la información se conserve cuando la aplicación se cierra de manera inesperada? | D19: ='3. Caracterización'!G46 -> 3 | E19: ='3. Caracterización'!H46 -> 0 | F19: ='3. Caracterización'!I46 -> 0 | G19: =SUM(D19:F19) -> 3
A20: 19 | B20: ='3. Caracterización'!A57 -> Confiabilidad | C20: ='3. Caracterización'!B57 -> ¿Se necesita que exista una prueba periódica de que las copias de respaldo efectivamente sirven? | D20: ='3. Caracterización'!G57 -> 0 | E20: ='3. Caracterización'!H57 -> 0 | F20: ='3. Caracterización'!I57 -> 3 | G20: =SUM(D20:F20) -> 3
A21: 20 | B21: ='3. Caracterización'!A78 -> Disponibilidad | C21: ='3. Caracterización'!B78 -> ¿Se necesita que el sistema avise cuando un dispositivo lleva demasiado tiempo sin sincronizar? | D21: ='3. Caracterización'!G78 -> 3 | E21: ='3. Caracterización'!H78 -> 0 | F21: ='3. Caracterización'!I78 -> 0 | G21: =SUM(D21:F21) -> 3
A22: 21 | B22: ='3. Caracterización'!A145 -> Capacidad | C22: ='3. Caracterización'!B145 -> ¿Se necesita prever un crecimiento del volumen de información año tras año sin cambiar de sistema? | D22: ='3. Caracterización'!G145 -> 0 | E22: ='3. Caracterización'!H145 -> 3 | F22: ='3. Caracterización'!I145 -> 0 | G22: =SUM(D22:F22) -> 3
A23: 22 | B23: ='3. Caracterización'!A148 -> Capacidad para ser Administrado | C23: ='3. Caracterización'!B148 -> ¿Se necesita poder cambiar los permisos de un usuario de manera inmediata? | D23: ='3. Caracterización'!G148 -> 0 | E23: ='3. Caracterización'!H148 -> 0 | F23: ='3. Caracterización'!I148 -> 3 | G23: =SUM(D23:F23) -> 3
A24: 23 | B24: ='3. Caracterización'!A151 -> Capacidad para ser Administrado | C24: ='3. Caracterización'!B151 -> ¿Se necesita poder crear variedades nuevas sin desarrollo adicional? | D24: ='3. Caracterización'!G151 -> 0 | E24: ='3. Caracterización'!H151 -> 3 | F24: ='3. Caracterización'!I151 -> 0 | G24: =SUM(D24:F24) -> 3
A25: 24 | B25: ='3. Caracterización'!A153 -> Capacidad para ser Administrado | C25: ='3. Caracterización'!B153 -> ¿Se necesita poder cambiar la densidad de siembra o los parámetros de cálculo sin desarrollo adicional? | D25: ='3. Caracterización'!G153 -> 0 | E25: ='3. Caracterización'!H153 -> 3 | F25: ='3. Caracterización'!I153 -> 0 | G25: =SUM(D25:F25) -> 3
A26: 25 | B26: ='3. Caracterización'!A158 -> Capacidad para ser Administrado | C26: ='3. Caracterización'!B158 -> ¿Se necesita poder actualizar la aplicación en todos los dispositivos sin recogerlos uno por uno? | D26: ='3. Caracterización'!G158 -> 0 | E26: ='3. Caracterización'!H158 -> 0 | F26: ='3. Caracterización'!I158 -> 3 | G26: =SUM(D26:F26) -> 3
A27: 26 | B27: ='3. Caracterización'!A167 -> Experiencia de Usuario | C27: ='3. Caracterización'!B167 -> ¿Se necesita reducir al mínimo la cantidad de toques necesarios para registrar una cama? | D27: ='3. Caracterización'!G167 -> 3 | E27: ='3. Caracterización'!H167 -> 0 | F27: ='3. Caracterización'!I167 -> 0 | G27: =SUM(D27:F27) -> 3
A28: 27 | B28: ='3. Caracterización'!A174 -> Experiencia de Usuario | C28: ='3. Caracterización'!B174 -> ¿Se necesita poder identificar la cama escaneando una marca física en lugar de escribir el código? | D28: ='3. Caracterización'!G174 -> 3 | E28: ='3. Caracterización'!H174 -> 0 | F28: ='3. Caracterización'!I174 -> 0 | G28: =SUM(D28:F28) -> 3
A29: 28 | B29: ='3. Caracterización'!A183 -> Seguridad | C29: ='3. Caracterización'!B183 -> ¿Se necesita que la sesión se cierre sola después de un tiempo sin uso? | D29: ='3. Caracterización'!G183 -> 0 | E29: ='3. Caracterización'!H183 -> 0 | F29: ='3. Caracterización'!I183 -> 3 | G29: =SUM(D29:F29) -> 3
A30: 29 | B30: ='3. Caracterización'!A209 -> Interoperatividad | C30: ='3. Caracterización'!B209 -> ¿Se necesita que la información se pueda leer desde una herramienta de análisis externa? | D30: ='3. Caracterización'!G209 -> 0 | E30: ='3. Caracterización'!H209 -> 3 | F30: ='3. Caracterización'!I209 -> 0 | G30: =SUM(D30:F30) -> 3
A31: 30 | B31: ='3. Caracterización'!A229 -> Capacidad para ser Soportado | C31: ='3. Caracterización'!B229 -> ¿Se necesita poder diagnosticar un problema sin tener que desplazarse hasta la finca? | D31: ='3. Caracterización'!G229 -> 0 | E31: ='3. Caracterización'!H229 -> 0 | F31: ='3. Caracterización'!I229 -> 3 | G31: =SUM(D31:F31) -> 3
A32: 31 | B32: ='3. Caracterización'!A230 -> Capacidad para ser Soportado | C32: ='3. Caracterización'!B230 -> ¿Se necesita poder revisar el estado de un dispositivo de forma remota? | D32: ='3. Caracterización'!G230 -> 0 | E32: ='3. Caracterización'!H230 -> 0 | F32: ='3. Caracterización'!I230 -> 3 | G32: =SUM(D32:F32) -> 3
A33: 32 | B33: ='3. Caracterización'!A237 -> Portabilidad | C33: ='3. Caracterización'!B237 -> ¿Se necesita que la aplicación de captura funcione en dispositivos Android? | D33: ='3. Caracterización'!G237 -> 3 | E33: ='3. Caracterización'!H237 -> 0 | F33: ='3. Caracterización'!I237 -> 0 | G33: =SUM(D33:F33) -> 3
A34: 33 | B34: ='3. Caracterización'!A7 -> Confiabilidad | C34: ='3. Caracterización'!B7 -> ¿Se necesita verificar que la información sea correcta de manera que se agrupe la información por finca y por jornada completa? | D34: ='3. Caracterización'!G7 -> 0 | E34: ='3. Caracterización'!H7 -> 2 | F34: ='3. Caracterización'!I7 -> 0 | G34: =SUM(D34:F34) -> 2
A35: 34 | B35: ='3. Caracterización'!A16 -> Confiabilidad | C35: ='3. Caracterización'!B16 -> ¿Se necesita que el sistema avise cuando se intenta capturar dos veces la misma cama el mismo día? | D35: ='3. Caracterización'!G16 -> 2 | E35: ='3. Caracterización'!H16 -> 0 | F35: ='3. Caracterización'!I16 -> 0 | G35: =SUM(D35:F35) -> 2
A36: 35 | B36: ='3. Caracterización'!A58 -> Confiabilidad | C36: ='3. Caracterización'!B58 -> ¿Se necesita que la aplicación avise cuando el almacenamiento del dispositivo está por llenarse? | D36: ='3. Caracterización'!G58 -> 2 | E36: ='3. Caracterización'!H58 -> 0 | F36: ='3. Caracterización'!I58 -> 0 | G36: =SUM(D36:F36) -> 2
A37: 36 | B37: ='3. Caracterización'!A84 -> Rendimiento | C37: ='3. Caracterización'!B84 -> ¿Se necesita que cada dato quede guardado de inmediato, sin espera perceptible? | D37: ='3. Caracterización'!G84 -> 2 | E37: ='3. Caracterización'!H84 -> 0 | F37: ='3. Caracterización'!I84 -> 0 | G37: =SUM(D37:F37) -> 2
A38: 37 | B38: ='3. Caracterización'!A85 -> Rendimiento | C38: ='3. Caracterización'!B85 -> ¿Se necesita que el paso de una pantalla a la siguiente sea inmediato aun sin conexión? | D38: ='3. Caracterización'!G85 -> 2 | E38: ='3. Caracterización'!H85 -> 0 | F38: ='3. Caracterización'!I85 -> 0 | G38: =SUM(D38:F38) -> 2
A39: 38 | B39: ='3. Caracterización'!A89 -> Rendimiento | C39: ='3. Caracterización'!B89 -> ¿Se necesita que muchos dispositivos puedan sincronizar al mismo tiempo al terminar la jornada sin que el sistema se degrade? | D39: ='3. Caracterización'!G89 -> 1 | E39: ='3. Caracterización'!H89 -> 0 | F39: ='3. Caracterización'!I89 -> 1 | G39: =SUM(D39:F39) -> 2
A40: 39 | B40: ='3. Caracterización'!A110 -> Capacidad para ser Auditado | C40: ='3. Caracterización'!B110 -> ¿Se necesita poder llegar, desde una cifra de un reporte, hasta los datos individuales que la componen? | D40: ='3. Caracterización'!G110 -> 0 | E40: ='3. Caracterización'!H110 -> 2 | F40: ='3. Caracterización'!I110 -> 0 | G40: =SUM(D40:F40) -> 2
...
