Workbook

Sheet Como leer
B2: Entrevista sesion 1 - Finca de flores - Director de produccion
B3: Respuestas tal como se registraron, con el analisis de lo que falta pregunta por pregunta.
B5: Que hay en este archivo
B6: Entrevista S1 | C6: Una fila por pregunta. A la izquierda lo que se pregunto y lo que respondio el cliente, sin editar. A la derecha, el analisis: en que estado quedo la respuesta, que falta exactamente, y el texto listo para volver a preguntarlo.
B7: Calificacion por bloque | C7: La calificacion del levantamiento recalculada desde las notas individuales de cada pregunta, en vez de por dimensiones. Se actualiza sola si cambias una nota.
B9: Como usar la columna 'Como volver a preguntarlo'
B10: Esta redactada para copiar | C10: El texto ya esta escrito como se lo dirias al cliente, en su tono. No lo reformules: mientras mas parezca una duda puntual y menos un cuestionario, mas facil es que te contesten.
B11: Una por mensaje | C11: Si mandas tres preguntas juntas por WhatsApp, te contestan la ultima. Manda maximo dos al dia.
B12: Siempre con salida facil | C12: Casi todas terminan ofreciendo un estimado o una opcion. Responder eligiendo cuesta mucho menos que responder explicando.
B14: Escala de las notas
B15: 5 - Completa | C15: Responde lo que se pregunto, con datos verificables. No hay que volver sobre ella.
B16: 4 - Completa con detalle menor | C16: Sirve para disenar. Falta un dato secundario que se cierra por mensaje.
B17: 3 - Parcial | C17: Contesto una parte o se quedo en lo general. Hay que volver con una pregunta mas concreta.
B18: 2 - Vaga o mal interpretada | C18: El cliente respondio otra cosa, o respondio sin datos. Casi siempre es culpa de como estaba formulada la pregunta.
B19: 1 - Contradictoria | C19: Choca con otra respuesta de la misma entrevista. No se resuelve preguntando de nuevo: se verifica con un documento o en campo.
B20: 0 - Sin responder | C20: Quedo en blanco. En este caso todo el bloque de cierre, que es lo mas urgente y lo mas facil de recuperar.

Sheet Entrevista S1
A1: Entrevista sesion 1 - respuestas y vacios
A2: Columnas A-D: lo registrado en la sesion, sin editar. Columnas E-J: analisis y accion. La columna H esta lista para copiar y enviar tal cual.
A4: ID | B4: Bloque | C4: Pregunta | D4: Respuesta del cliente | E4: Estado | F4: Nota /5 | G4: Que falta o quedo mal interpretado | H4: Como volver a preguntarlo (listo para copiar) | I4: Contexto añadido por el cliente | J4: Prioridad | K4: Canal | L4: Seguimiento
A5: P01 | B5: B0. Encuadre | C5: Presentacion: objetivo de la sesion, duracion, permiso para grabar y aclaracion de que hoy no hablaremos de tecnologia. | D5: Recolectar información para generar reportes e informes dentro de producción y ventas, estos informes deben ser presentados en BI spreadsheets, informes dínamico. | E5: Parcial | F5: 3 | G5: No quedo registrado el encuadre en si (permiso de grabacion, tiempo disponible). Mas importante: la respuesta introduce 'BI, spreadsheets, informes dinamicos' sin definir nada. No se sabe que es un informe dinamico para el cliente, ni si eso vive en el PowerBI que ya tienen o seria algo nuevo. Es la ambiguedad de alcance mas cara del proyecto. | H5: Cuando dices informes dinamicos, me muestras uno que ya usen y uno que les gustaria tener? Eso saldria del PowerBI que ya tienen o seria algo nuevo dentro del sistema? | I5: De estos informes se cuenta con muestras ya realizadas de lo que se busca, antes se realizaba haciendo estimaciones con powerBI pero se busca poder recrear estas estimaciones directamente y con el enfoque del negocio. O se pueden mejorar ya que estas no se adaptan completamente al negocio. Planteando un enfoque diferente. | J5: Critica | K5: Reunion | L5: Abierto
A6: P02 | B6: B0. Encuadre | C6: Cual es tu rol y desde cuando estas en la finca? | D6: El rol del usuario era director de producción: Responsabilidades: - Verifica que la información recolectada correcta - Ejecuta presupuesto de producción- Realiza el presupuesto de proyección y ventas, realiza el presupuesto de gastos de la empresa, y toma desiciones con base en la producción (Lo que se está cosechandoy cómo está creciendo). | E6: Parcial | F6: 4 | G6: Responsabilidades claras y buen nivel de autoridad. Falta la antiguedad, que indica cuanto conocimiento tacito acumula, y quien decide cuando el no esta. Si todo el modelo de proyeccion vive en su cabeza, es un riesgo de dependencia clave. | H6: Cuanto llevas en la finca? Y si tu no estas, quien toma las decisiones de produccion? | I6: 30 años | Hay 4 personas encargadas de las desicione con 4 roles diferentes, gerente de producción, jefe de planeación gerente de ventas, gerente general, alguno de estos 3 pueden tomar desiciones. | J6: Media | K6: Reunion | L6: Abierto
A7: P03 | B7: B1. Negocio y objetivo | C7: Cuentame que produce la finca y a quien le venden. | D7: La finca produce: -Diferentes variedades de flores, vende la flor terminada ya cosechada, cuarto frio, buquetes, entre otros productos del negocio 9 variedades de flor con diferentes morfologías. | E7: Parcial | F7: 3 | G7: Contesto solo la mitad: que producen. Falta por completo a quien le venden, que era el punto de la pregunta. Sin eso no se sabe si la proyeccion es para exportacion o mercado nacional, ni si hay contratos o venta spot. Ademas quedaron dos cajones sin abrir: 'cuarto frio' como producto sugiere servicio a terceros, y 'entre otros productos' puede esconder lineas de negocio enteras. | H7: Me falto la otra mitad: a quien le venden? Exportacion o nacional, y en que proporcion? Son clientes fijos con contrato o venta spot? Y cuando dices cuarto frio como producto, es un servicio que le prestan a terceros? | I7: Por el momento dentro del proyecto no está contemplado manejar clientes y ventas. | J7: Alta | K7: Reunion | L7: Abierto
A8: P04 | B8: B1. Negocio y objetivo | C8: Que tamano tiene la operacion? | D8: 15 hectareas de producción de florez: Repartidos de la siguiente forma: --Finca o predio con Hectareas 15 que contiene bloques (Que no son necesariamente las mismas áreas) Las áreas de producción son espacios. Estos bloques están compuestos Naves, y las navez están compuestas por camas. y dentro de las camas están las variedades de flor. | E8: Parcial | F8: 4 | G8: La jerarquia quedo perfecta y es lo mas valioso de la sesion: finca > bloque > nave > cama > variedad, con la aclaracion de que los bloques no tienen la misma area. Falta el conteo: cuantos bloques, naves y camas hay. Ese numero define el volumen de datos y si la captura por cama es viable o hay que muestrear. Tampoco se sabe cuanta gente trabaja en campo y poscosecha, que es el numero de usuarios. | H8: Dos numeros que me faltan: cuantos bloques, naves y camas hay en total? Y cuantas personas trabajan en campo y en poscosecha? | I8: Aproximadamente 25 bloques, 1525 camas, 156 operarios de campo, 10 administradores, postcosecha son 57 personas y 4 administradores (Personal indirecto: Supervisores auxiliares gerentes ingenieros), se puede saber cuantos plantaciones hay en una cama, dependiendo del área de la cama y la variante que se quiera sembrar se define una cantidad de plantaciones por metro cuadrado y esto es definido por el ingeniero agronomo | J8: Alta | K8: Reunion | L8: Abierto
A9: P05 | B9: B1. Negocio y objetivo | C9: Que te llevo a buscar un sistema ahora y no hace dos anos? | D9: Ahora las fincas se encuentran más organizadas y sistematizadas al estar más organizadas necesitan datos más certeros, porque la producción demora 3.4 meses para producir con una diferencia de tiempo cómo para que u productor sepa que tanto hay, se necesita la información para saber cómo va a resultar esa flor más adelante. | E9: Parcial | F9: 3 | G9: Explico el contexto del sector, no el disparador de ESTA finca. El dato bueno que si dio es que el ciclo de 3.4 meses obliga a decidir con mucha anticipacion, y eso justifica el proyecto. Falta el evento concreto y, sobre todo, quien patrocina el proyecto y si hay presupuesto aprobado. | H9: Paso algo puntual este ano que los hizo decidirse? Y dentro de la empresa, quien esta empujando el proyecto? | I9: La empresa desea mejorar el motor de base de datos y llevar los datos que tiene actualmente a una plataforma más robusta, y tener una aplicación Mobile-First y web | J9: Media | K9: Reunion | L9: Abierto
A10: P06 | B10: B1. Negocio y objetivo | C10: Si esto funciona perfecto, que es distinto dentro de un ano? | D10: Eficiensa en toma de desiciones y venta a partir de estadisticas. | E10: Vaga | F10: 2 | G10: 'Eficiencia en la toma de decisiones' no es una meta, es un deseo. Sin un numero al que comprometerse, nadie va a poder declarar el proyecto exitoso ni fallido, y tu no vas a poder defender el precio. Lo bueno es que con los datos de P28 ya tienes con que proponer la meta tu mismo. | H10: Te propongo tres metas concretas y me dices si te sirven: (1) que gerencia vea el dato en menos de 24 horas en vez de 8 dias; (2) eliminar las 4 horas semanales de digitacion; (3) bajar el error de captura del 2% a menos de 0.5%. Cambiarias alguna? | I10: Los ejemplos dados aplican cómo metas, tener proyecciones de ventas que se acerquen del 90% al 110% con base a desviaciones: Yo tengo una flor que tengo para florecer 1000 unidades en semana 25 el sistema debe decir, usted va a decidir según las deviaciones, esos 1000 plantados realmente se van a reflejar en 900 mantener esa información al día esl o importante. se busca 1000, pero pueden salir más o menos productos cultivados, y que el sistema pueda mantener el seguimiento de estos cambios. el 90% y 110% se aplica directamente a la información proyectada es decir al 900, puedo sacar 810 o 990 o 1000 pero si saco 1020 algo no funcionó | J10: Alta | K10: Reunion | L10: Abierto
A11: P07 | B11: B1. Negocio y objetivo | C11: Que decisiones tomas hoy con la proyeccion de ventas? | D11: Hacer una venta a futuro más real 2. minimizar. Las cancelaciones de ventas por falta de productos obtener un mejor retorno de venta, por tener más certera la producción, y que el cliente tenga mejor confianza hacia la empresa. | E11: Completa | F11: 4 | G11: Los cuatro usos quedaron claros. Falta cuantificarlos, que es lo que convierte esto en argumento de venta: cuantas ventas se cancelaron el ano pasado y cuanto costo comprarle a terceros para cumplir. | H11: El ano pasado, mas o menos cuantas ventas se cancelaron por falta de producto y cuanto tuvieron que comprarle a terceros? Un orden de magnitud me sirve. | I11: un 8% del total de ventas planeadas se tuvo que conseguir mediante terceros o cancelando ordenes, por diferentes motivos no solo de cultivo. | J11: Alta | K11: Reunion | L11: Abierto
A12: P07b | B12: B1. Negocio y objetivo | C12: Que decisiones tomas hoy con la proyeccion de producción? | D12: 1. Baja de costos 2. Proyectar una necesidad de personal 3. Hacer cambio de variedades y/o productos que no son rentables para produccción, tener mejores datos para la obtención de nuevos productos. | E12: Completa | F12: 4 | G12: Muy buena respuesta y bien que la separaras de la de ventas. Pero abre un alcance oculto grande: 'cambiar variedades que no son rentables' exige cruzar produccion con costos y precios. Hoy no sabemos si esos datos existirian dentro del sistema o habria que traerlos de contabilidad. | H12: Para saber que variedad no es rentable hay que cruzar produccion con costos y precio de venta. Esos datos de donde saldrian? El sistema los tendria que guardar o vienen de contabilidad? | I12: No es el enfoque del proyecto ya que no vamos a manejar ventas directamente | J12: Alta | K12: Reunion | L12: Abierto
A13: P08 | B13: B1. Negocio y objetivo | C13: Quien mas usa o necesita esa proyeccion? | D13: Hay distintas áreas: Planeación, Producción, Ventas, Compras y el área administrativa y / o gerencial (Con privilegios). | E13: Parcial | F13: 3 | G13: Buena lista de areas, sin profundidad. No hay nombres de contactos, ni que necesita ver cada area. 'Compras' aparece aqui y no se vuelve a mencionar en toda la entrevista: no sabemos que necesita. Y el 'con privilegios' de gerencia contradice de frente lo que dijo en P38. | H13: Me puedes dar el nombre y contacto de planeacion, ventas y compras? Y en una linea, que necesita ver cada uno? Especialmente compras, que no alcanzamos a tocar. | I13: No contamos con más personas para recopilar información además no es necesario ventas y compras | J13: Alta | K13: Reunion | L13: Abierto
A14: P09 | B14: B2. Estructura del cultivo | C14: Dibujame como esta organizado el cultivo, de la finca hacia abajo. | D14: (sin respuesta) | E14: Sin responder | F14: 2 | G14: Quedo cubierta en parte por P04, pero falta lo que realmente importa del modelo de datos: la nomenclatura. Como se identifica una cama, si los codigos se repiten entre bloques, y si cambian cuando se renueva. Esa es la llave primaria de todo el sistema; si se equivoca, se rehace todo. | H14: Me pasas un plano de la finca, aunque sea a mano? Y dime como se llama una cama en concreto, por ejemplo la primera del bloque 1. Ese codigo se repite en otro bloque? Cambia cuando renuevan? | J14: Critica | K14: Reunion | L14: Abierto
A15: P10 | B15: B2. Estructura del cultivo | C15: Que variedades tienen y como estan distribuidas? | D15: Normalmente: Hay una variedad por cama; esa variedad puede tener varios colores, se puede llegar a dar el caso de mezclar dos variedades por cama, en una misma cama pueden haber distintas subvariedades, en una etapa de producción hay 9 variedades activas constantemente. Estas variedades terminan su ciclo entre 3 y 5 meses dependiendo la variedad, se pueden cambiar después de la producción, sembrando otra variedad o la misma variedad. | E15: Completa | F15: 4 | G15: Excelente. Confirma variedad por cama como norma, con la excepcion de mezcla, y agrega dos niveles que no estaban previstos: colores y subvariedades dentro de una misma cama. Eso cambia el modelo de datos. Falta el catalogo real de las 9 variedades y cada cuanto se da la mezcla. | H15: Me pasas la lista de las 9 variedades con sus subvariedades y colores? Y cada cuanto pasa que una cama tenga dos variedades mezcladas, es raro o es comun? | I15: Hay 300 variedades y subvariedades no es rentable mencionarlas todas. | J15: Alta | K15: Reunion | L15: Abierto
A16: P11 | B16: B2. Estructura del cultivo | C16: Como es el ciclo de una variedad, desde siembra hasta el corte? | D16: El ciclo de una variedad del sembrado al corte es entre 3 a 5 meses dependiendo la variedad, dentro del ciclo hay una serie de variedades que pueden o no afectar la producción, dependiendo de la variedad pueden salir diferentes tamaños de corte. | E16: Parcial | F16: 3 | G16: Hay una ambiguedad que hay que resolver: dijo 'dentro del ciclo hay una serie de variedades que pueden o no afectar la produccion'. Probablemente quiso decir VARIABLES, no variedades. Si es asi, esas variables son justo lo que hay que registrar. Y falta lo mas importante para el motor de calculo: una cama no corta todo en un dia. Cuantos dias dura el periodo de corte y cuantos cortes da una planta. | H16: Dos cosas. Primero, cuando dijiste que dentro del ciclo hay variedades que afectan la produccion, te referias a variables o factores? Cuales son? Segundo: cuando una cama empieza a cortar, cuantos dias sigue cortando, y cuantos cortes da una planta antes de terminar? | I16: No es variedades que afecten producción sinó actividades que afectan esta producción: Por ejemplo, desbotone, corte de luces, retirada de luces a destiempo, profundida de la siembra. | J16: Critica | K16: Reunion | L16: Abierto
A17: P12 | B17: B2. Estructura del cultivo | C17: Cuanto se corre ese ciclo por clima u otras causas? | D17: La producción se puede adelantar por clima, ambiente, activiades humanas o quimicamente puede haber variedades en el tiempo estipulado. | E17: Vaga | F17: 2 | G17: Enumero causas pero no dio un solo numero. Sin saber cuantos dias se corre el ciclo, la proyeccion no puede dar un rango de confianza ni avisar cuando algo se esta desviando. La frase final ('puede haber variedades en el tiempo estipulado') quedo incompleta en la nota. | H17: En dias: cuanto se te ha corrido un ciclo en el peor caso que recuerdes? Y lo normal, cuantos dias arriba o abajo? | I17: El mejor caso es que la producción se pueda cosechar en la fecha estipulada, el peor de los casos puede atrasarse hasta 15 días, un margen de error del 16% por encima o por debajo,la idea del producto es mermar ese margen de error | J17: Alta | K17: Reunion | L17: Abierto
A18: P13 | B18: B2. Estructura del cultivo | C18: Cuando renuevan o erradican un area y como lo manejan? | D18: Se realiza el mismo proceso de preparar camas, cuando se termina la cosecha se puede repetir el proceso, si la cama tiene muchos problemas puede erradicar la plantación y solucionar antes de interrumpir el ciclo, la desición la toma el ingeniero de producción o gerente de ventas puede interrumpir un ciclo, porque no hay ventas, porque hay problemas fitosanitarios o viene enferma. | E18: Completa | F18: 4 | G18: Muy buena, y revela una regla de negocio fuerte: se puede interrumpir un ciclo por decision comercial, no solo sanitaria. Falta la frecuencia anual y, sobre todo, que pasa con lo que ya estaba proyectado y vendido de esa cama. Tambien falta el tiempo muerto de preparacion entre ciclos, que reduce la capacidad real del ano. | H18: Cuando se erradica una cama a mitad de ciclo, que pasa con lo que ya estaba proyectado y vendido de ahi? Cada cuanto pasa al ano? Y cuanto se demora preparar una cama antes de volver a sembrar? | I18: Tiene que ser digitada la información de la destrucción de la cama para que el sistema reste esas unidades y lo que pasa con lo vendido no es nuestro dominio, pero las opciones son o cancelar o comprar, esta erradicación puede presentarse semanalmente o incluso diario. Después de erradicado, se determina según la necesidad de la finca que se hace con esa cama. | J18: Media | K18: Reunion | L18: Abierto
A19: P14 | B19: B2. Estructura del cultivo | C19: Manejan siembras escalonadas para apuntar a fechas? | D19: Durante temporada se busca que el presupuesto de ventas y producción permita realizar una siembra escalonada para abastecer estas fechas. | E19: Parcial | F19: 3 | G19: Confirmo que escalonan para temporada, pero no como. Y hay una decision de alcance escondida: quieres que el sistema CALCULE cuando sembrar para llegar a una fecha (planeacion inversa, modulo grande) o solo que REGISTRE lo que ya decidieron (mucho mas simple). Son dos proyectos distintos. | H19: Necesito cerrar algo de alcance: quieres que el sistema te diga cuando hay que sembrar para llegar con flor a San Valentin, o solo que registre la siembra que tu ya decidiste? A o B. | I19: Es mantener la información sin necesidad de advertir, cada año es muy variable en temporadas altas, pero si el sistema es inteligente puede genera sugeridos. | J19: Alta | K19: Reunion | L19: Abierto
A20: P15 | B20: B3. Proyeccion hoy | C20: Llevame por el ultimo ejercicio de proyeccion que hiciste, paso a paso. | D20: Al sembrar el producto tengo un estimado de cuanto se va a producir dentro de el ciclo de esa variedad, conociendo todas sus caracteristicas. Con esa producción si preguntan la planeación de cómo va la flor miro los datos y sé en que cama está, voy físicamente a ver cómo va su desarrollo si está adelantada o atrasada, también se pueden hacer desiciones tomando la información con la idea de poder realizar una baja en porcentaje de producción, también se puede agregar o quitar días para la fecha de corte, bajar 5% de producción (Bajar producción se refiere a: Cómo se tiene estimado y se espera que la tierra tenga resultados especificos, pero en algún momento del proceso pasa algo y cierta parte del producto no funciona para venta y ahí se realiza una baja de producción estimada para las proyecciones. La Pérdida se mide por porcentajes y / o tallos)haciendo una observación física, no hay una herramienta predilecta para hacer este proceso. | E20: Parcial | F20: 3 | G20: Es la respuesta mas rica de la entrevista y a la vez la mas insuficiente. Describe como DECIDE, no como CALCULA. Buenisimo que hayas capturado su definicion de 'baja de produccion' en sus palabras. Pero faltan los tres numeros del motor: de donde sale el estimado inicial de tallos, como se reparte ese total en el tiempo, y con que criterio baja 5% y no 10%. | H20: Necesito reconstruir tu calculo con un caso real. Escoge una cama cualquiera y llevamos sus numeros: esquejes sembrados, fecha, cuantos tallos esperabas, cuando empezo a cortar, cuantos dias duro y cuantos tallos salieron. Con un ejemplo completo entiendo la logica. | I20: Cama de 1000 plantas sembradas al término de 3 a 5 meses de diferentes actividades que se hacen en la cama, de acuerdo a las proyecciones de producción de la variedad, se pueden sacar 900, y esto se calcular mediante porcentajes de producción. La realidad no puede exceder 1000 plantas, el corte dura 7 días en promedio dependiendo de la variedad, todo depende del producto. | J20: Critica | K20: Reunion | L20: Abierto
A21: P16 | B21: B3. Proyeccion hoy | C21: Como hacen el aforo? | D21: El sistema debe realizar el conteo y la proyección no quiere decir directamente que se cuente flor por flor pero si estimados; Desde planeación me dicen que debo de plantar y que tanto utilizar lo que permite que la propia información de planeación de una proyección inicial del caso. | E21: Mal interpretada | F21: 2 | G21: Respondio sobre lo que quiere del sistema futuro, no sobre lo que hacen hoy. Pero de rebote solto el dato mas importante de toda la entrevista: 'desde planeacion me dicen que debo plantar y que tanto'. Es decir, la proyeccion NO nace en produccion, nace en un plan de siembra que entrega planeacion. Ese actor y ese documento nunca se exploraron. | H21: Volviendo a lo de hoy: planeacion te entrega un plan de siembra por escrito? Me pasas un ejemplo? Y ese plan de donde sale, del presupuesto de ventas del ano? | J21: Critica | K21: Reunion | L21: Abierto
A22: P17 | B22: B3. Proyeccion hoy | C22: Que estados fenologicos registran en el aforo? | D22: Actividades que pueden dificultar la producción de algún producto, está la siembra y puede afectar la productividad, lo defino cómo diferentes actividades durante la producción, aplicación de hormonas; Las etapas son "Siembra" "Desbotone" "Botón Color"; Desbotone es una variedades que necesita quitarle ciertas partes de la planta para que puedan salir de mejor calidad el producto. BotónColor: El momento previo al corte. | E22: Mal interpretada | F22: 2 | G22: La pregunta estaba mal formulada de mi lado: 'estado fenologico' es vocabulario de rosa y aqui no aplico. El cliente entendio 'actividades que dificultan la produccion'. Aun asi rescato tres etapas (siembra, desbotone, boton color) y definio dos. Falta lo unico que importa: cuantos dias hay de cada etapa al corte, y si esas tres son todas. | H22: Creo que te hice la pregunta enredada. Te la pongo simple: si hoy voy y veo una cama en desbotone, en cuantos dias empieza el corte? Y si la veo en boton color? Ademas de esas dos, hay otras etapas que reconozcan a ojo? | I22: Todo depende de la variedad, pero normalmente es 2 a 3 semanas después del desbotone, si está en boton color se planea cortar en 2 o 3 días. | J22: Critica | K22: Reunion | L22: Abierto
A23: P18 | B23: B3. Proyeccion hoy | C23: Como pasan de tallos aforados a tallos vendibles? | D23: Esto ya había sido abordado previamente dónde la persona encargada de la proyección realiza una revisión presencial de la cama y estima restando procentajes si la producción va bajando, y además agrega o quita dias a la fecha de corte | E23: Parcial | F23: 2 | G23: Remite a P15 sin agregar la regla. El porcentaje de baja sigue siendo criterio personal no documentado. Falta saber si ese ajuste queda registrado en alguna parte y si se puede reconstruir por que una proyeccion cambio. | H23: Cuando bajas un 5% la produccion de una cama, eso queda anotado en algun lado con la razon? Si alguien pregunta dentro de tres meses por que bajo, se puede reconstruir? | I23: Se hace un formato de baja de producción y se debe digitar en el sistema para que pueda ser calculada la proyección, esta información se recopila cada semana. | J23: Critica | K23: Reunion | L23: Abierto
A24: P19 | B24: B3. Proyeccion hoy | C24: Como clasifican la produccion para vender? | D24: La flor se clasifica en grados o calidades: GRADOS: El grado es una forma de indicar un conjunto de CALIDADES de un producto , CALIDADES: La longitud del tallo Tamaños de la flor, número de flores por tallo y grosor del tallo, y follaje, cada finca define sus calidades y grados. | E24: Parcial | F24: 3 | G24: Definicion conceptual muy buena y util: grado agrupa calidades (longitud, tamano de flor, numero de flores por tallo, grosor y follaje) y cada finca define las suyas. Falta todo lo operativo: el catalogo de grados de esta finca y el porcentaje historico que cae en cada grado. Sin eso la proyeccion solo puede dar un total de tallos, que comercialmente no sirve. | H24: Me pasas la tabla de grados y calidades que usan ustedes? Y de una cosecha tipica, mas o menos que porcentaje sale en cada grado? Un estimado tuyo sirve si no esta medido. | J24: Alta | K24: Reunion | L24: Abierto
A25: P20 | B25: B3. Proyeccion hoy | C25: En que unidad de tiempo proyectan? | D25: Siempre se proyecta en días, se pueden utliizar semanas pero al final el principal son días. | E25: Completa | F25: 4 | G25: Dato claro y con consecuencia fuerte: si proyectan en dias a un ano, son cientos de puntos por cama y por variedad. Hay que confirmar si el presupuesto anual tambien es diario o es mensual, porque son dos granularidades y hoy estan mezcladas. | H25: El presupuesto a un ano lo armas en dias o en meses? Y el seguimiento semanal, a que nivel lo miras? Son la misma pantalla para ti o dos cosas distintas? | I25: El presupuesto se arma días semanas meses despendiendo a quien le interesa, al gerente le interesa ver mensualmente y cuanto va a ingresar, al gerente de ventas le interesa semanal y diario con prioridad en semanal, y al gerente de producción le interesa diario | J25: Alta | K25: Reunion | L25: Abierto
A26: P21 | B26: B3. Proyeccion hoy | C26: Con cuanta anticipacion necesitan la proyeccion? | D26: 1 año de anticipación para la proyección y la realización de su presupuesto, y en ocasiones se hace hasta 1 año y medio dependiendo de la variedad, debe manterse el seguimiento de producción yventas ajustando el presupuesto a una realidad y calidad, con la proyección de producción se realizan las ventas. | E26: Completa | F26: 4 | G26: Horizonte confirmado: 1 a 1.5 anos. Cambia la naturaleza del sistema, es presupuesto y no pronostico de corto plazo. Falta cada cuanto se vuelve a proyectar y quien aprueba el presupuesto. | H26: Cada cuanto vuelves a ajustar la proyeccion, semanal o mensual? Y quien aprueba el presupuesto una vez lo armas? | I26: La proyección se realiza mensualmente o según necesidad, lo ideal es realizar la proyección semanalmente. | J26: Media | K26: Reunion | L26: Abierto
A27: P22 | B27: B3. Proyeccion hoy | C27: Que tan cerca queda la proyeccion de lo que realmente cortan? | D27: La desviación de presupuesto de ventas vs la proyección normalmente está 6% debajo del presupuesto | E27: Parcial | F27: 3 | G27: El 6% es un numero valioso, pero compara presupuesto contra proyeccion, no proyeccion contra corte real. Si se usa como linea base sin aclararlo, la meta del proyecto queda mal fijada desde el primer dia. | H27: Ese 6%, compara lo presupuestado contra lo proyectado, o contra lo que efectivamente se corto? Tienen el dato de proyectado contra cortado real de los ultimos meses, aunque sea de una variedad? | I27: Lo presupuestado contra lo que se cortó realmente, hay información de los ultimos meses más adelante se obtendrá. | J27: Alta | K27: Reunion | L27: Abierto
A28: P23 | B28: B3. Proyeccion hoy | C28: Que pasa cuando la proyeccion falla, por encima o por debajo? | D28: Cuando se incumple la proyección el gerente de ventas debe suplir la necesidad del producto, comprando a terceros, o cancelando ventas | E28: Parcial | F28: 3 | G28: Las dos salidas quedaron claras (comprar a terceros o cancelar). Falta el costo, que es exactamente el argumento economico que necesitas para justificar el proyecto ante gerencia. | H28: Cuantas veces al ano les toca comprar a terceros o cancelar? Y cuanto les costo aproximadamente el ano pasado? | I28: Es dificil estipular un número porque puede ocurrir semanalmente o mensualmente. Se puede ir un 6% de las ventas en comprar a terceros. | J28: Alta | K28: Reunion | L28: Abierto
A29: P24 | B29: B3. Proyeccion hoy | C29: Ajustan la proyeccion a mano por experiencia? | D29: La proyección se ajusta a base en las productividades que arroja el sistema: Por ejepmplo, si de X variedad, requiero que proyecte el 90%, pero la realidad es 80%, que hace la produducción, planeación dice "Estamos producciendo menos de lo que estamos proyectando o más de lo que estamos proyectando", siendo a mano por las personas encargadas de la producción. | E29: Parcial | F29: 3 | G29: Confirma que el ajuste es manual y por experiencia. Pero vuelve a mencionar 'las productividades que arroja el sistema', que es la tercera vez que aparece un sistema del que no sabemos nada. Ademas menciona una comparacion proyectado contra real que aparentemente ya existe. | H29: Cuando dices que el sistema arroja las productividades, a que sistema te refieres? Podemos verlo en pantalla? Y esa comparacion de lo proyectado contra lo real, ya la saca el sistema o la hacen a mano? | I29: Tiene un nombre pero no lo recordamos pero existe un pantallazo o información accesible. | J29: Critica | K29: Reunion | L29: Abierto
A30: P25 | B30: B3. Proyeccion hoy | C30: Como se cruza la proyeccion con los pedidos ya comprometidos? | D30: Esta visualización es una adiccion a las ventas, el usuario sugiere que se sale del dominio del sistema que se busca, se le puede adicionar que se pueda especificar para que clientes van las camas definidas. Una finca puede contar con demasiados clientes, para proyectar de manera individual a caada cliente puede ser demasiado complicado y engorroso. Pero se puede dejar abierto. | E30: Parcial | F30: 2 | G30: Quedo en 'se sale del dominio pero se puede dejar abierto', que no es una decision: es alcance que reaparece a mitad del desarrollo. Ademas aparecio una funcionalidad nueva y grande sin dimensionar: asignar camas especificas a clientes especificos. Y contradice P07, donde el objetivo era minimizar cancelaciones de venta, que es justo esto. | H30: Necesito cerrarlo con opciones: A) el sistema solo muestra cuanta flor vamos a tener. B) ademas muestra cuanta ya esta comprometida y con que cliente. Si es B, entra en la primera fase o la dejamos para una segunda? Dime A, B1 o B2. | I30: El sistema sólo muestra cuanta flor se va a producir y tener para las proyecciones sin meterse en el terreno de ventas. | J30: Alta | K30: Reunion | L30: Abierto
A31: P26 | B31: B4. Registro continuo | C31: Que se registra hoy sobre el estado del cultivo? | D31: Se registra 1 cosa: La siembra, lo ideal es registrar más actividades, está digitalizado pero no lo hace la finca, es necesario un sistema amigable y rápido de ingresar. Lo realmente necesario es la siembra y la producción de esa cama y la producción de un esqueje, no se registran actividades, pero se puede hacer para que registre cualquier cosa: La siembra se define cómo: Poner esqueje en la cama y sembrarlo y empieza su ciclo fenologico. | E31: Parcial | F31: 4 | G31: Respuesta clave: hoy solo se registra la siembra. Delimita bien el punto de partida. Pero hay una frase que no cierra: 'esta digitalizado pero no lo hace la finca'. Hay que aclarar si la herramienta existe y no la usan, o si la usa un tercero. Y aparece 'la produccion de un esqueje', que apunta a un modulo de material vegetal que no se exploro. | H31: Cuando dices que esta digitalizado pero la finca no lo hace, a que te refieres? Existe la herramienta y no la usan, o lo hace alguien externo? Y lo del esqueje: manejan produccion propia de material vegetal? | I31: Las actividades para la cama pueden estár digitalizadas pero la finca no realiza esta acción, la herramienta está pero no se hace. | J31: Alta | K31: Reunion | L31: Abierto
A32: P27 | B32: B4. Registro continuo | C32: Quien registra, donde y en que momento del dia? | D32: Un digitador practicante de sistemas, hay un supervisor de siembra que realiza formularios y luego el prácticante digita. Lo puede hacer cualquier persona, pero cómo son varios focos de siembra, una solo rol que realiza esto, supervisores o auxiliares de siembra, cómo hay distintos puntos de siembra este auxiliar, separando por bloques o variedades, básicamente este supervisor puede revistar cantidad de bloques o revisar variedad cultivada. | E32: Completa | F32: 4 | G32: Cadena de captura clara: supervisor llena formato, practicante digita. Falta cuantos supervisores y auxiliares hay, que es el numero de usuarios. Y hay un riesgo que conviene nombrar: si el digitador es un practicante, rota cada semestre y se lleva el conocimiento. | H32: Cuantos supervisores y auxiliares de siembra hay en total? Y el practicante que digita, es un cargo fijo o cambia cada semestre? | I32: 3 Personas ocupadas de realizar ingreso de información de campo, 1 supervisor y 2 auxiliares, Esta información es vista por alrededor de 20 personas, el practicante va cambiando semestral y hay una brecha entre cada semestre hay que utilizar 15 días de entrenamiento. | J32: Media | K32: Reunion | L32: Abierto
A33: P28 | B33: B4. Registro continuo | C33: Cuanto tarda hoy ese registro y cuanto se pierde en el camino? | D33: El supervisor toma la información daria mediante plantillas y formatos que el supervisor llena a lapiz y papel tomando nota en un formato, se tarda 1 hora al día tomando información, el prácticante de sistemas digitando esta información en el sistema puede tardar 4 horas 1 vez a la semana y planeación y gerencía recibe esta información cada 8 días, esta información tiene un porcentaje de error del 2%. | E33: Completa | F33: 5 | G33: La mejor respuesta de toda la entrevista y la base economica del proyecto: 1 hora diaria, 4 horas semanales de digitacion, 8 dias de latencia, 2% de error. Lo unico que falta es de donde sale ese 2%: si esta medido o es una impresion. Y si la hora diaria es por supervisor o en total. | H33: Ese 2% de error esta medido en algun lado o es tu impresion? Y la hora diaria de captura, es por cada supervisor o entre todos? | I33: Es información la revisa supervisor y luego auditor que suele ser ingeniero en sistemas, la idea es que se elimine este error. Siempre ocurre semanalmente este 2%, esta información es comparación de producto real contra la proyección realizada. | J33: Media | K33: Reunion | L33: Abierto
A34: P29 | B34: B4. Registro continuo | C34: Hay senal de celular o wifi dentro del cultivo? | D34: NO | E34: Contradictoria | F34: 3 | G34: La respuesta es clara y decisiva para la arquitectura, pero choca de frente con P30, donde dice que el formato de plagas se llena en celular y va directo a un sistema. Ambas no pueden ser ciertas. Falta ademas saber donde SI hay senal: oficina, poscosecha, entrada. | H34: Me quedo una duda: si no hay senal en el cultivo, el formato de plagas que llenan en el celular en que momento sube? Lo llenan en la cama y sube despues, o lo llenan ya afuera? Y donde si hay wifi, en oficinas? | I34: Local en celular, luego se sube en la nube cuando ya haya red, en las oficinas normalmente | J34: Critica | K34: Reunion | L34: Abierto
A35: P30 | B35: B4. Registro continuo | C35: Que registran de plagas y enfermedades? | D35: Se registran plagas y enfermedades, es un formato que se encuentra en un celular, y va directamente en un sistema. | E35: Contradictoria | F35: 3 | G35: Confirma que ya existe captura movil funcionando para plagas. Eso es una pista fuerte del sistema actual y ademas un precedente util: si esa app la usan, sirve de modelo. Falta saber cual es, quien la hizo y si es el mismo sistema del que habla en P24 y P33. | H35: Ese formato de plagas del celular, que app es y quien la hizo? Es el mismo sistema del que hablabas antes? Me puedes mostrar una pantalla? | I35: Se llama Monitoreo de Plagas y enfermedades. Es un sistema propio de la empresa. | J35: Critica | K35: Reunion | L35: Abierto
A36: P31 | B36: B4. Registro continuo | C36: Registran clima? | D36: El clima se registra manual, cón información principal cómo pluviometría en mililitros de lluvia. | E36: Parcial | F36: 3 | G36: Solo registran pluviometria y de forma manual. Hay un hueco logico importante: en P12 dijo que el ciclo se corre por clima, pero no miden temperatura. Sin esa variable no se puede modelar el corrimiento ni mejorar la proyeccion con el tiempo. | H36: Ademas de lluvia, miden temperatura o humedad en algun lado? Si el ciclo se corre por clima y solo medimos lluvia, no vamos a poder explicarlo. Tienen estacion meteorologica o seria viable poner una? | I36: Se registra temperatura y humedad pero no se hace nada en la producción con esta información, Si hay estación meteorologica pero no está en uso. | J36: Media | K36: Reunion | L36: Abierto
A37: P32 | B37: B4. Registro continuo | C37: Que reportes se producen hoy y para quien? | D37: Se Sacan reportes de siembra. Reportes de producción. Reportes de plagas y enfermedades. Reportes de inventarios de material vegetal. Reportes de pérdida de flor Reportes de estimados de flor. Pueden haber más, y generalmente se realizan de manera semanal estos reportes son digitales a través de powerBI | E37: Completa | F37: 5 | G37: Excelente inventario: siembra, produccion, plagas y enfermedades, inventarios de material vegetal, perdida de flor, estimados de flor. Semanales y en PowerBI. Todo reporte que existe hoy es un requisito del sistema nuevo. Falta verlos y saber quien los construye y mantiene. | H37: Me puedes compartir esos reportes tal como salen hoy, aunque sea en captura de pantalla? Y quien arma y mantiene los tableros de PowerBI? | J37: Critica | K37: Reunion | L37: Abierto
A38: P33 | B38: B4. Registro continuo | C38: Que pasa cuando alguien registra un dato equivocado? | D38: El sistema normalmente no permite ingresar información erronea pero si esta información erronea llega a otras étapas de debe poder realizar una trazabilidad completa hasta la cama de dónde salió esta información | E38: Parcial | F38: 3 | G38: Dejo un requisito muy claro y bien formulado: trazabilidad completa hasta la cama de origen. Pero vuelve a aparecer 'el sistema' sin identificar. Y no contesto lo que se preguntaba: que pasa hoy cuando alguien ya registro mal, quien puede corregir y si queda rastro. | H38: Hoy, si un supervisor anota mal una cantidad y ya quedo registrada, quien la puede corregir? Queda constancia de quien la cambio y por que? | I38: Esta información la puede corregir al área de sistemas aprobado por el area de producción o gerente de producción o ingeniero agronomo | J38: Alta | K38: Reunion | L38: Abierto
A39: P34 | B39: B5. Excepciones y limites | C39: Que es lo que mas tiempo te quita hoy en todo esto? | D39: La revisión de la siembra es lo que más tiempo consume, realizar la captura de datos, el foco del proyecto. | E39: Completa | F39: 4 | G39: Declaracion de foco del proyecto en boca del cliente, que es lo mejor que se puede tener: la captura de datos de la siembra. Solo falta cuantificar cuanto tiempo le quita a el personalmente. | H39: De tu semana, cuantas horas se te van en revisar siembra y captura de datos? | I39: Se pueden ir 4 horas semanalmente | J39: Baja | K39: Reunion | L39: Abierto
A40: P35 | B40: B5. Excepciones y limites | C40: Que se hace hoy por fuera del sistema o de las planillas oficiales? | D40: Todo está sistematizado. | E40: Contradictoria | F40: 1 | G40: 'Todo esta sistematizado' choca de frente con lo que el mismo dijo en P28 (papel y lapiz, 4 horas de digitacion) y P31 (clima manual). No esta mintiendo: describe la intencion de la finca, no su realidad. Esta respuesta no se discute en reunion, se verifica en campo. | H40: No la vuelvas a preguntar. Pidele al supervisor: me mandas foto de los formatos de esta semana, tal como quedan llenos? Y ve un dia a campo a mirar. | J40: Critica | K40: Reunion | L40: Abierto
A41: P36 | B41: B5. Excepciones y limites | C41: Que otros sistemas existen en la finca? | D41: Sistema de nómina y contabilidad. | E41: Parcial | F41: 2 | G41: Solo nombro las categorias. Falta lo que sirve: que sistemas son, quien los administra, y si el sistema nuevo tendria que leer o escribir algo de ellos. Si hay que calcular rentabilidad por variedad (P07b), contabilidad deja de ser opcional. | H41: Que sistemas de nomina y contabilidad usan, y quien los administra? El sistema nuevo tendria que intercambiar datos con alguno o son mundos separados? | I41: Es un mundo totalmente aparte fuera del alcance | J41: Alta | K41: Reunion | L41: Abierto
...

Sheet Calificacion por bloque
B2: Calificacion del levantamiento, recalculada desde cada pregunta
B3: Promedio de las notas individuales de la hoja Entrevista S1. Si cambias una nota alla, esto se actualiza solo. Reemplaza la calificacion por dimensiones de la version anterior.
B5: Bloque de la entrevista | C5: Preguntas | D5: Nota media /5 | E5: Equivale /10 | F5: Lectura
B6: B0. Encuadre | C6: =COUNTIF('Entrevista S1'!$B$5:$B$50,$B6) -> 2 | D6: =IFERROR(AVERAGEIF('Entrevista S1'!$B$5:$B$50,$B6,'Entrevista S1'!$F$5:$F$50),0) -> 3.5 | E6: =D6*2 -> 7 | F6: El encuadre cumplio, pero la respuesta de apertura ya introdujo la ambiguedad mas cara del proyecto: informes en BI sin definir si es el PowerBI actual o algo nuevo.
B7: B1. Negocio y objetivo | C7: =COUNTIF('Entrevista S1'!$B$5:$B$50,$B7) -> 7 | D7: =IFERROR(AVERAGEIF('Entrevista S1'!$B$5:$B$50,$B7,'Entrevista S1'!$F$5:$F$50),0) -> 3.2857143 | E7: =D7*2 -> 6.5714286 | F7: El bloque mas solido despues del de captura. Se entiende el negocio y para que sirve la proyeccion. Falla en lo mismo de siempre: ninguna meta tiene numero y no se pregunto a quien le venden.
B8: B2. Estructura del cultivo | C8: =COUNTIF('Entrevista S1'!$B$5:$B$50,$B8) -> 6 | D8: =IFERROR(AVERAGEIF('Entrevista S1'!$B$5:$B$50,$B8,'Entrevista S1'!$F$5:$F$50),0) -> 3 | E8: =D8*2 -> 6 | F8: Lo mejor de la sesion. La jerarquia quedo lista para modelar. Los huecos son de detalle: nomenclatura de camas, catalogo de variedades y cuantos dias se corre un ciclo.
B9: B3. Proyeccion hoy | C9: =COUNTIF('Entrevista S1'!$B$5:$B$50,$B9) -> 11 | D9: =IFERROR(AVERAGEIF('Entrevista S1'!$B$5:$B$50,$B9,'Entrevista S1'!$F$5:$F$50),0) -> 2.8181818 | E9: =D9*2 -> 5.6363636 | F9: El bloque mas importante y el peor resuelto. El cliente describio como decide, no como calcula. Aqui se juega la viabilidad del proyecto: sin la formula no hay nada que programar.
B10: B4. Registro continuo | C10: =COUNTIF('Entrevista S1'!$B$5:$B$50,$B10) -> 8 | D10: =IFERROR(AVERAGEIF('Entrevista S1'!$B$5:$B$50,$B10,'Entrevista S1'!$F$5:$F$50),0) -> 3.75 | E10: =D10*2 -> 7.5 | F10: Bien cuantificado y con el foco del proyecto declarado por el propio cliente. Arrastra la contradiccion de conectividad y las menciones sueltas a un sistema que ya existe.
B11: B5. Excepciones y limites | C11: =COUNTIF('Entrevista S1'!$B$5:$B$50,$B11) -> 8 | D11: =IFERROR(AVERAGEIF('Entrevista S1'!$B$5:$B$50,$B11,'Entrevista S1'!$F$5:$F$50),0) -> 2.125 | E11: =D11*2 -> 4.25 | F11: Bloque debil. Casi todo quedo en respuestas de una linea o contradictorias. Es donde suelen esconderse los sobrecostos: integraciones, permisos, certificacion y disponibilidad.
B12: B6. Cierre | C12: =COUNTIF('Entrevista S1'!$B$5:$B$50,$B12) -> 4 | D12: =IFERROR(AVERAGEIF('Entrevista S1'!$B$5:$B$50,$B12,'Entrevista S1'!$F$5:$F$50),0) -> 0 | E12: =D12*2 -> 0 | F12: No se hizo. Es la parte mas facil de recuperar y la mas urgente: un correo resuelve el 80% hoy mismo.
B13: GLOBAL DE LA SESION 1 | C13: =COUNT('Entrevista S1'!$F$5:$F$50) -> 46 | D13: =IFERROR(AVERAGE('Entrevista S1'!$F$5:$F$50),0) -> 2.7391304 | E13: =D13*2 -> 5.4782609 | F13: Sobre 10. Comparable con la calificacion ponderada del archivo de diagnostico.
B15: Conteo por estado de respuesta
B16: Completa | C16: =COUNTIF('Entrevista S1'!$E$5:$E$50,$B16) -> 10
B17: Parcial | C17: =COUNTIF('Entrevista S1'!$E$5:$E$50,$B17) -> 21
B18: Vaga | C18: =COUNTIF('Entrevista S1'!$E$5:$E$50,$B18) -> 3
B19: Mal interpretada | C19: =COUNTIF('Entrevista S1'!$E$5:$E$50,$B19) -> 2
B20: Contradictoria | C20: =COUNTIF('Entrevista S1'!$E$5:$E$50,$B20) -> 4
B21: Sin responder | C21: =COUNTIF('Entrevista S1'!$E$5:$E$50,$B21) -> 6
B23: Preguntas criticas abiertas | C23: =COUNTIFS('Entrevista S1'!$J$5:$J$50,"Critica",'Entrevista S1'!$L$5:$L$50,"Abierto") -> 15
B26: Por que esta nota no coincide con la del archivo de diagnostico
B27: Este promedio trata las 46 preguntas como si pesaran lo mismo, y no pesan igual. El archivo de diagnostico pondera por dimension y da una nota mas baja, porque castiga que las brechas esten justo donde el proyecto se juega la viabilidad: el motor de calculo y la frontera con lo que ya existe. Usa esta hoja para ver donde re-preguntar, y la ponderada para decidir si ya puedes estimar. Mientras haya preguntas criticas abiertas, la respuesta es no.
