Workbook

Sheet Diagnostico
B2: Diagnostico y plan de accion - Sesion 1 con el Director de Produccion
B3: Archivo independiente. Las respuestas de la entrevista y el analisis pregunta por pregunta viven en '2_ENTREVISTA_S1_Diligenciada_y_Vacios.xlsx'. La plantilla en blanco es '1_PLANTILLA_Levantamiento_Requisitos.xlsx'.
B4: AVISO: esta hoja es el registro historico de la sesion 1 y no se ha modificado. El estado actual del levantamiento, con la calificacion recalculada tras la sesion 2 del 04-ago-2026, esta en la hoja 'Estado tras Sesion 2'.
B6: Resumen general
B7: La sesion salio muy bien en el terreno donde el entrevistado vive todos los dias: la estructura fisica del cultivo, el ciclo de las variedades, y sobre todo el dolor operativo de la captura de datos. Ese ultimo bloque quedo cuantificado, que es exactamente lo que se necesita para justificar el proyecto: 1 hora diaria del supervisor llenando formatos a lapiz, 4 horas semanales del practicante digitando, 8 dias de latencia hasta que planeacion y gerencia ven el dato, y un 2% de error declarado.
B8: La sesion se quedo corta donde el proyecto se juega su viabilidad: el motor de proyeccion y la frontera del sistema. El cliente describio COMO decide, no COMO calcula. Frases como 'voy fisicamente a ver como va su desarrollo', 'bajar 5% de produccion' y 'no hay una herramienta predilecta' describen un juicio experto, no un algoritmo. Nadie puede programar eso todavia.
B9: Hay un problema mayor y facil de pasar por alto: el cliente menciona un sistema que ya existe. Dijo 'las productividades que arroja el sistema' (P24), 'el sistema normalmente no permite ingresar informacion erronea' (P33), 'va directamente a un sistema' (P30) y 'todo esta sistematizado' (P35). Ademas ya producen reportes semanales en PowerBI (P32) y en la apertura pidio informes en BI (P01). Nunca se pregunto que sistema es, quien lo administra, ni por que no basta. Se esta levantando requisitos como si el terreno estuviera vacio y no lo esta.
B10: Ese mismo 'todo esta sistematizado' contradice de frente lo que el mismo entrevistado conto en P28 (papel y lapiz) y P31 (clima manual). No es que este mintiendo: esta describiendo la intencion de la finca, no su realidad. Es la respuesta tipica que hay que ir a verificar en campo, no discutir en la reunion.
B11: El horizonte cambia el problema por completo. Proyectan a 1 y hasta 1.5 anos (P21) y en dias (P20). Eso no es un pronostico de cosecha de corto plazo: es un presupuesto anual que despues se ajusta contra la realidad. Son dos funciones distintas con granularidades distintas y hoy estan mezcladas en una sola conversacion.
B12: El bloque de cierre se perdio entero. Sin validacion del resumen, sin nombres de otros entrevistados, sin datos de muestra y sin segunda sesion agendada. Es la parte mas facil de recuperar y la mas urgente: cuatro preguntas por mensaje resuelven el 80% de eso hoy mismo.
B14: Calificacion de contexto por dimension
B15: Dimension | C15: Nota /10 | D15: Peso | E15: Ponderado | F15: Por que esa nota
B16: Objetivo de negocio y metrica de exito | C16: 6 | D16: 0.08 | E16: =C15*D15 | F16: El disparador esta claro (ciclo de 3-5 meses obliga a decidir con mucha anticipacion) y los usos de la proyeccion son concretos. Pero 'eficiencia en toma de decisiones' no es una meta medible: no hay un numero que el proyecto se comprometa a mover.
B17: Modelo del dominio: jerarquia, variedades, ciclos | C17: 8 | D17: 0.12 | E17: =C16*D16 | F17: Lo mejor de la sesion. Finca > bloque > nave > cama > variedad, 15 ha, 9 variedades activas, ciclo de 3 a 5 meses, subvariedades y colores dentro de una cama, renovacion y erradicacion explicadas. Con esto ya se puede dibujar el modelo de datos.
B18: Logica de proyeccion: el motor de calculo | C18: 4 | D18: 0.18 | E18: =C17*D17 | F18: Es el corazon del sistema y esta descrito como juicio experto, no como formula. Falta: de donde sale la productividad esperada por variedad, como se distribuye la produccion en el tiempo (una cama no corta todo en un dia), y con que criterio se aplica el porcentaje de baja. Sin esto no hay nada que programar.
B19: Captura de datos en campo | C19: 8 | D19: 0.12 | E19: =C18*D18 | F19: Muy bien cuantificado: 1 h/dia del supervisor, 4 h/semana de digitacion, 8 dias de latencia, 2% de error, sin senal en el cultivo, y el propio cliente declaro que este es el foco del proyecto (P34). Falta solo confirmar el 2% y ver los formatos reales.
B20: Clasificacion comercial: grados y calidades | C20: 5 | D20: 0.08 | E20: =C19*D19 | F20: El concepto quedo claro y bien explicado (grado agrupa calidades: longitud, tamano, numero de flores, grosor, follaje) y que cada finca los define. Falta lo operativo: el catalogo de grados de ESTA finca y el porcentaje historico que cae en cada uno por variedad.
B21: Sistemas existentes e integraciones | C21: 2 | D21: 0.15 | E21: =C20*D20 | F21: La brecha mas peligrosa. Hay al menos un sistema en uso, PowerBI produciendo reportes semanales, y nomina y contabilidad de fondo. Nada de eso fue explorado. No se sabe si el proyecto reemplaza, alimenta o convive.
B22: Frontera del alcance | C22: 3 | D22: 0.1 | E22: =C21*D21 | F22: El cruce con pedidos quedo en 'se sale del dominio pero se puede dejar abierto' (P25), que no es una decision. Y no esta definido si el entregable es la capa de captura que alimenta el BI actual o un sistema de reportes nuevo. Esa sola ambiguedad puede duplicar el costo.
B23: Roles, permisos y seguridad | C23: 3 | D23: 0.04 | E23: =C22*D22 | F23: Contradiccion directa: P38 dice que todos pueden ver todo, pero P08 habla de gerencia 'con privilegios'. Nunca se toco costos ni precios de venta, que es justo lo que suele restringirse.
B24: Requisitos no funcionales | C24: 3 | D24: 0.05 | E24: =C23*D23 | F24: Solo hay un numero: la temporada pico es 60% mayor. Falta volumen diario de registros, usuarios concurrentes, cuanto tiempo pueden operar caidos y con que dispositivos cuentan los supervisores. 'Perderia todo su valor si falla' es un sentimiento, no un requisito.
B25: Regulatorio (Florverde) | C25: 3 | D25: 0.03 | E25: =C24*D24 | F25: Se identifico el sello y su proposito, pero no que registros exige, con que formato ni cada cuanto auditan. Como es no negociable, conviene cerrarlo temprano.
B26: Cobertura de stakeholders y validacion | C26: 2 | D26: 0.05 | E26: =C25*D25 | F26: Una sola persona entrevistada, para un sistema que segun el mismo cliente sirve a planeacion, produccion, ventas, compras y gerencia. Y el cierre no se hizo: sin resumen validado, sin contactos, sin datos, sin segunda sesion.
B27: CALIFICACION GLOBAL DE CONTEXTO | C27: =SUMPRODUCT(C15:C25,D15:D25) | D27: =SUM(D15:D25) | E27: =SUM(E15:E25) | F27: Sobre 10. Interpretacion abajo.
B29: Que significa esa nota
B30: 8 - 10 | C30: Listo para estimar y arrancar diseno detallado.
B31: 6 - 7.9 | C31: Suficiente para una propuesta de solucion y un estimado con rango amplio. Faltan cierres puntuales.
B32: 4 - 5.9 | C32: Alcanza para un concepto de solucion y una propuesta comercial preliminar. NO alcanza para estimar esfuerzo ni para empezar a construir. Es donde esta este caso.
B33: < 4 | C33: Solo alcanza para saber que hay un problema. Cualquier cifra que des sera un invento.
B35: Lo que hiciste bien y conviene repetir
B36: Registraste vocabulario del cliente en sus propias palabras (desbotone, boton color, baja de produccion, esqueje). Eso vale oro: te permite hablar su idioma en la proxima sesion y detectar despues cuando dos personas usan el mismo termino distinto.
B37: Anotaste las definiciones que el cliente dio por su cuenta, como la de 'baja de produccion' y la de 'siembra'. Esas definiciones son reglas de negocio disfrazadas.
B38: Partiste P07 en dos (proyeccion de ventas y proyeccion de produccion) al notar que el cliente distinguia entre ambas. Adaptar el guion en vivo es exactamente lo correcto.
B39: Conseguiste numeros donde importaba: 15 ha, 9 variedades, 3-5 meses de ciclo, 1 h/dia, 4 h/semana, 8 dias, 2%, 6%, 60%. Un levantamiento sin cifras no se puede defender ante nadie.
B42: Relacion con la calificacion del archivo 2
B43: El archivo 2 califica pregunta por pregunta y da un promedio simple de 5.5 sobre 10. Esta hoja pondera por dimension y da 4.6. La diferencia no es un error: el promedio simple trata las 46 preguntas como si pesaran lo mismo. La ponderada castiga que las brechas esten justo donde el proyecto se juega la viabilidad, que es el motor de calculo y la frontera con lo que ya existe. Usa el archivo 2 para saber que re-preguntar y esta hoja para decidir si ya puedes estimar.

Sheet Estado tras Sesion 2
B2: Estado del levantamiento tras la sesion 2
B3: Actualizado el 05-ago-2026. La hoja 'Diagnostico' se conserva sin tocar como registro historico de la sesion 1. Esta hoja la reemplaza como foto actual.
B5: Que paso en la sesion 2 (04-ago-2026)
B6: La sesion recorrio las brechas de este archivo una por una, hizo el taller de atributos de calidad y cerro la definicion de roles. Fue una sesion de cierre, no de descubrimiento, y por eso rindio tanto: de 20 brechas abiertas, 9 quedaron cerradas y 7 avanzaron a parcial.
B7: El avance mas importante no es el numero de brechas cerradas sino DONDE se cerraron. La frontera del alcance paso de 3 a 8: el cruce con pedidos y clientes queda fuera de la fase 1, Florverde queda fuera, personal e insumos quedan fuera. Esa sola definicion es la que evitaba que el proyecto costara el doble.
B8: El motor de proyeccion, que era la brecha que hundia la calificacion, dejo de ser juicio experto y paso a tener estructura: area de cama por densidad de siembra da las plantas, plantas por porcentaje de productividad da los tallos, y hay un tope duro del 100% que funciona como validacion. Todavia faltan el origen del porcentaje y la curva de reparto en los 7 dias de corte, pero ya hay algo que programar.
B9: Se resolvieron las cuatro contradicciones de la sesion 1. La conectividad no era contradiccion sino arquitectura offline-first. El 'todo esta sistematizado' se referia a las actividades, no a la siembra. El 6% compara presupuestado contra cortado real. Y las 'variedades dentro del ciclo' eran ACTIVIDADES.
B10: Lo que no avanzo nada: los documentos. Plan de siembra, presupuestos, formatos en papel llenos, tabla de grados, historico por cama. Todo se volvio a prometer y nada llego. Hoy ese es el bloqueo real del proyecto, no las preguntas.
B11: Aparecieron cinco brechas nuevas al analizar la transcripcion. La mas seria es BR-21: el 6% actual y el +/-10% de meta no parecen medirse al mismo nivel de agregacion, y de eso depende la linea base del proyecto.
B13: Calificacion de contexto por dimension
B14: Dimension | C14: Sesion 1 | D14: Ahora | E14: Peso | F14: Por que cambio
B15: Objetivo de negocio y metrica de exito | C15: 6 | D15: 9 | E15: 0.08 | F15: El cliente acepto las tres metas propuestas (dato en menos de 24 h en vez de 8 dias, eliminar las 4 h de digitacion, bajar el error de captura) y anadio una cuarta suya con numero: proyecciones dentro del +/-10%. Ya hay algo que se puede declarar cumplido o incumplido.
B16: Modelo del dominio: jerarquia, variedades, ciclos | C16: 8 | D16: 8 | E16: 0.12 | F16: Gano mucho detalle: 25 bloques, ~1525 camas, densidad de siembra por m2 definida por el agronomo, corte de ~7 dias, desbotone a corte 3 semanas, boton color a corte 12 dias. Pero aparecio la contradiccion de 9 contra 300 variedades (BR-22), que compensa la ganancia.
B17: Logica de proyeccion: el motor de calculo | C17: 4 | D17: 6 | E17: 0.18 | F17: De juicio experto a formula parcial. Ya hay estructura, unidades y un tope duro que sirve de validacion. Sigue sin resolverse de donde sale el porcentaje de productividad por variedad y como se reparte el corte en el tiempo (BR-23).
B18: Captura de datos en campo | C18: 8 | D18: 9 | E18: 0.12 | F18: La conectividad quedo resuelta como offline-first, con un precedente que ya funciona en la finca (la app de plagas). Se cuantificaron los usuarios: 3 capturan, ~12 usan, ~20 consultan. Falta la foto de los formatos y el volumen de registros en dia pico.
B19: Clasificacion comercial: grados y calidades | C19: 5 | D19: 5 | E19: 0.08 | F19: No avanzo. El catalogo se volvio a pedir y se volvio a quedar en 'esta dentro del sistema'. Sin el, la proyeccion solo da un total de tallos, que comercialmente no sirve para vender.
B20: Sistemas existentes e integraciones | C20: 2 | D20: 4 | E20: 0.15 | F20: Se supo el PARA QUE (migrar el motor de base de datos a algo robusto, con app movil y web) y que PowerBI se replantea con otro enfoque. Pero el sistema sigue sin nombre, sin pantallazo y sin export. Sigue siendo la brecha que mas puede cambiar el proyecto.
B21: Frontera del alcance | C21: 3 | D21: 8 | E21: 0.1 | F21: El salto mas grande de la sesion. Fuera de fase 1: cruce con pedidos y clientes, Florverde, personal e insumos. Dentro: captura offline, proyeccion, erradicaciones, trazabilidad y parametrizacion. Ya se puede escribir un documento de alcance.
B22: Roles, permisos y seguridad | C22: 3 | D22: 8 | E22: 0.04 | F22: Tres roles definidos con permisos concretos. La unica restriccion real es el precio de venta frente a supervisores y auxiliares; entre bloques no hay restriccion. Se acabo la contradiccion entre 'todos ven todo' y 'gerencia con privilegios'.
B23: Requisitos no funcionales | C23: 3 | D23: 7 | E23: 0.05 | F23: Se priorizaron 14 atributos de calidad, se fijo la tolerancia de caida en ~1 hora con plan B en papel, y el pico se desgloso: +60% tallos, +60% registros, +30-40% personal. Falta el volumen absoluto de registros en dia pico.
B24: Regulatorio (Florverde) | C24: 3 | D24: 8 | E24: 0.03 | F24: No se resolvio: se EXCLUYO del alcance por decision explicita del cliente. Una exclusion documentada vale tanto como un requisito cerrado, porque elimina el riesgo de descubrirlo tarde.
B25: Cobertura de stakeholders y validacion | C25: 2 | D25: 3 | E25: 0.05 | F25: Si hubo validacion del entendimiento de la sesion 1, que es lo que faltaba. Pero el cliente rechazo ampliar la lista de entrevistados, asi que planeacion, ventas y calidad siguen sin voz. Es un riesgo aceptado, no cerrado (BR-25).
B26: CALIFICACION GLOBAL DE CONTEXTO | C26: =ROUND(SUMPRODUCT(C15:C25,E15:E25),1) | D26: =ROUND(SUMPRODUCT(D15:D25,E15:E25),1) | E26: =SUM(E15:E25) | F26: Sobre 10, ponderado por dimension. Las celdas son formulas: si cambias una nota o un peso, el global se recalcula solo.
B28: Como se lee esa nota
B29: 8 - 10 | F29: Listo para estimar esfuerzo y arrancar diseno detallado.
B30: 6 - 7.9 | F30: Suficiente para una propuesta de solucion y un estimado con rango amplio. Faltan cierres puntuales. ES DONDE ESTA EL PROYECTO AHORA.
B31: 4 - 5.9 | F31: Alcanza para un concepto de solucion. No alcanza para estimar ni construir. Aqui estaba tras la sesion 1.
B32: < 4 | F32: Solo alcanza para saber que hay un problema.
B34: El cliente se autocalifico
B35: 5 / 10 | F35: Al final de la sesion 2, sobre el contexto que habia entregado: 'de uno sobre 10 es un 5. Esta muy mal, por eso hay que volverla a hacer y por eso saque estas preguntas, y posiblemente toca volverlas a hacer hasta conseguir un 9 con algo'. Su 5 y el 6.7 de arriba no miden lo mismo: el califica lo que el explico, esta hoja califica lo que quedo documentado. Que el cliente pida llegar a 9 es la mejor senal de la sesion: no hay que convencerlo de seguir profundizando.
B37: Conteo de brechas
B38: Cerradas | C38: =COUNTIF('Brechas y Contradicciones'!J5:J29,"Cerrada")
B39: Parciales | C39: =COUNTIF('Brechas y Contradicciones'!J5:J29,"Parcial")
B40: Abiertas | C40: =COUNTIF('Brechas y Contradicciones'!J5:J29,"Abierta")
B41: Criticas que siguen sin cerrar | C41: =COUNTIFS('Brechas y Contradicciones'!B5:B29,"Critica",'Brechas y Contradicciones'!J5:J29,"<>Cerrada")
B42: Total de brechas registradas | C42: =COUNTA('Brechas y Contradicciones'!A5:A29)
B44: Lo unico que importa ahora
B45: 1 | F45: Los documentos. Plan de siembra, presupuesto de produccion, formatos en papel llenos, tabla de grados y el detalle completo de UNA cama real. Nada avanza de verdad hasta que lleguen, y ya se pidieron dos veces.
B46: 2 | F46: BR-21: a que nivel se miden el 6% y el +/-10%. De eso depende la metrica de exito del proyecto, y hoy la meta propuesta parece mas floja que lo que la finca ya consigue.
B47: 3 | F47: BR-23: de donde sale el porcentaje de productividad por variedad y como se reparte el corte en los 7 dias. Es el ultimo hueco del motor.
...

Sheet Brechas y Contradicciones
A1: Brechas, contradicciones y como cerrarlas
A2: Ordenado por criticidad. Actualizado el 05-ago-2026 con los resultados de la sesion 2 (04-ago). Verde = cerrada. Amarillo = parcial, avanzo pero falta algo. Naranja = abierta. Las columnas K y L dicen que respondio la sesion 2 y que sigue faltando. BR-21 a BR-25 son brechas nuevas detectadas al analizar la sesion 2.
A4: ID | B4: Criticidad | C4: Tipo | D4: Tema | E4: Evidencia en la entrevista | F4: Por que importa | G4: Pregunta exacta que debes hacer | H4: A quien | I4: Canal | J4: Estado | K4: Que respondio la sesion 2 (04-ago-2026) | L4: Que falta todavia
A5: BR-01 | B5: Critica | C5: Brecha | D5: Sistema actual sin identificar | E5: P24: 'las productividades que arroja el sistema'. P33: 'el sistema normalmente no permite ingresar informacion erronea'. P30: 'va directamente a un sistema'. P35: 'todo esta sistematizado'. | F5: Ya existe software en operacion y no sabemos cual, quien lo administra, que guarda ni por que no basta. Sin esto no se puede decidir si el proyecto reemplaza, alimenta o convive con lo que hay, y esa decision cambia el costo por completo. | G5: Cuando dices 'el sistema', a cual te refieres exactamente? Como se llama, quien lo administra, que modulos usan hoy y que es lo que no les esta resolviendo? Podemos ver una pantalla y sacar un export de ejemplo? | H5: Director de produccion + TI | I5: Reunion 30 min | J5: Parcial | K5: Confirmado que el sistema existe y arroja productividades en tallos. El cliente NO recordo el nombre: 'el nombre se me olvido'. Dijo que se puede sacar un pantallazo. Aparecio el motivo real del proyecto: 'mejorar el motor de base de datos, llevar los datos actuales a una base robusta, y tener una aplicacion enfocada a celulares y web'. | L5: Nombre del sistema, quien lo administra, un pantallazo y un export de ejemplo. Sigue sin decidirse si FlorLogic reemplaza, alimenta o convive.
A6: BR-02 | B6: Critica | C6: Brecha | D6: Frontera con PowerBI | E6: P01: 'los informes deben ser presentados en BI, spreadsheets, informes dinamicos'. P32: 'los reportes son digitales a traves de PowerBI', semanales. | F6: No esta definido si el entregable es la capa de captura que alimenta el PowerBI que ya existe, o un sistema de reportes nuevo que lo reemplaza. Es la diferencia entre un proyecto y otro que cuesta el doble. | G6: El PowerBI que tienen hoy se queda y nosotros le entregamos los datos, o quieren que el sistema nuevo genere sus propios informes y el PowerBI desaparezca? Quien construye y mantiene esos tableros hoy? | H6: Director + quien arma el BI | I6: Reunion 30 min | J6: Parcial | K6: 'Lo de PowerBI esta y se utiliza, pero no es la forma mas optima que puede tener el negocio. No es que no sirva, se puede mejorar cambiando el enfoque.' | L6: Decision binaria sin tomar: el PowerBI se queda y le entregamos datos, o el sistema nuevo genera sus propios informes. Y quien construye y mantiene los tableros hoy.
A7: BR-03 | B7: Critica | C7: Brecha | D7: El motor de proyeccion no esta definido | E7: P15: 'tengo un estimado de cuanto se va a producir', 'voy fisicamente a ver como va', 'bajar 5% de produccion'. P16: 'no quiere decir que se cuente flor por flor pero si estimados'. P24: ajuste a mano. | F7: Es el corazon del sistema y hoy es juicio experto, no formula. Faltan las tres piezas del calculo: productividad esperada por variedad, curva de distribucion del corte en el tiempo, y regla del porcentaje de baja. | G7: Necesito reconstruir tu calculo con un caso real. Tomemos una cama concreta: cuantos esquejes sembraste, cuantos tallos esperabas, en cuantos dias empezo a cortar, cuantos dias duro el corte y cuantos tallos salieron por dia. Con un ejemplo me basta para entender la logica. | H7: Director de produccion | I7: Taller 60 min | J7: Parcial | K7: Destrabada la estructura del calculo: plantas_sembradas = area_cama_m2 x densidad_siembra(variedad), donde la densidad la define el ingeniero agronomo (ej. 60 o 90 plantas/m2). tallos_proyectados = plantas_sembradas x %productividad(variedad), del orden de 80-90%. Tope duro: nunca mas del 100% de las plantas sembradas; si excede, hay dato malo. El corte de una cama dura ~7 dias. | L7: Tres piezas: (1) de donde sale el %productividad por variedad; (2) como se distribuyen los tallos en los ~7 dias de corte, no hay curva; (3) con que criterio se aplica el porcentaje de baja. Ver BR-23.
A8: BR-04 | B8: Alta | C8: Brecha | D8: Etapas y dias a corte | E8: P17: el cliente respondio sobre actividades que dificultan la produccion. Dio solo 'Siembra', 'Desbotone' y 'Boton Color', sin dias asociados. La pregunta no se entendio. | F8: Sin la tabla variedad x etapa -> dias faltantes al corte no hay forma de convertir una observacion de campo en una fecha. Es el parametro que hace funcionar todo lo demas. | G8: Para una variedad cualquiera, si hoy veo una cama en desbotone, en cuantos dias empieza el corte? Y si la veo en boton color? Esos dias son iguales en todas las variedades o cambian? Que hace que se corran? | H8: Director de produccion | I8: Reunion o audio | J8: Parcial | K8: Desbotone -> corte = ~3 semanas. Boton color -> corte = ~12 dias. 'Todo depende de la variedad'. El cliente no quiso anadir mas etapas por ahora. El ciclo se corre hasta 15 dias, que sobre ~90 dias es un 6% de margen. | L8: La tabla variedad x etapa -> dias a corte de ESTA finca. Los numeros que dio son indicativos y genericos.
A9: BR-05 | B9: Alta | C9: Contradiccion | D9: Conectividad en campo | E9: P29: 'NO' hay senal ni wifi. P30: el registro de plagas 'es un formato que se encuentra en un celular y va directamente a un sistema'. | F9: Ambas no pueden ser ciertas al mismo tiempo. De la respuesta correcta depende si la app debe funcionar sin conexion, que es una decision de arquitectura, no un detalle. | G9: Me quedo una duda: si no hay senal en el cultivo, el formato de plagas que llenan en el celular, en que momento sube al sistema? Lo llenan en campo y sube despues, o lo llenan cuando ya salieron del bloque? Hay wifi en oficinas o en poscosecha? | H9: Supervisor de campo | I9: WhatsApp | J9: Cerrada | K9: RESUELTA, no era contradiccion. La app de plagas es 'totalmente celular local, se hace local y luego se sube a la nube'. Es arquitectura offline-first y es una app propia de la empresa (formato de monitoreo de plagas y enfermedades). Confirma que ya hay precedente de captura movil offline funcionando en la finca. | L9: Nada critico. Util pedir capturas de esa app como modelo de referencia.
A10: BR-06 | B10: Media | C10: Contradiccion | D10: Grado real de sistematizacion | E10: P35: 'todo esta sistematizado'. Pero P28: el supervisor llena formatos a lapiz y papel y un practicante digita 4 h/semana. P31: el clima se registra manual. | F10: El cliente esta describiendo la intencion de la finca, no su realidad. Si se toma literal, se subestima el trabajo de migracion y de cambio cultural. | G10: No la preguntes: pidela en fisico. 'Me pasas foto de los formatos que llena el supervisor esta semana, tal como quedan llenos?' | H10: Supervisor de campo | I10: WhatsApp | J10: Parcial | K10: Aclarado el malentendido: 'se hace lapiz y papel y luego se ingresa al sistema, que es lo que vamos a obviar'. Lo de 'todo esta sistematizado' se referia a las ACTIVIDADES: 'pueden estar digitalizadas pero no lo hace la gente'. 'La herramienta esta, lo que pasa es que no se usa'. | L10: La foto de los formatos en papel llenos sigue sin llegar. Es el artefacto que mas informacion da por menos esfuerzo.
A11: BR-07 | B11: Alta | C11: Decision pendiente | D11: Alcance del cruce con pedidos | E11: P25: 'se sale del dominio del sistema... pero se puede dejar abierto'. | F11: 'Dejarlo abierto' no es una decision, es alcance que reaparece a mitad del desarrollo. Ademas el cliente ya dijo en P07 que quiere minimizar cancelaciones de venta, que es justamente esto. | G11: Para la primera fase necesito cerrarlo: el sistema muestra solo cuanto vamos a tener, o tambien cuanto ya esta comprometido y a que cliente? Si es lo segundo, entra en fase 1 o lo dejamos para fase 2 y lo escribimos asi? | H11: Director + gerente de ventas | I11: Reunion 20 min | J11: Cerrada | K11: DECISION TOMADA. El cliente eligio la opcion A: 'solamente va a mostrar que flor se va a producir'. El cruce con pedidos y clientes queda FUERA de la fase 1. Motivo textual: 'porque se alarga mucho'. | L11: Nada. Dejarlo escrito en el documento de alcance para que no reaparezca.
A12: BR-08 | B12: Media | C12: Brecha | D12: Presupuesto anual vs proyeccion operativa | E12: P21: proyectan a 1 y hasta 1.5 anos para armar presupuesto. P20: la unidad es dias. P15: ajuste continuo por inspeccion fisica. | F12: Son dos funciones distintas: un presupuesto anual grueso y un seguimiento fino de corto plazo. Hoy estan mezcladas. Si se disenan como una sola, ninguna de las dos queda bien. | G12: Cuando armas el presupuesto a un ano, lo haces en dias o en meses? Y el seguimiento semanal contra ese presupuesto, a que nivel de detalle lo revisas? Son la misma pantalla o dos cosas distintas para ti? | H12: Director de produccion | I12: Reunion 20 min | J12: Cerrada | K12: El presupuesto se arma en dias, semanas o meses segun quien lo consume: gerencia general mensual (plata que entra y sale), gerente de ventas semanal, gerente de produccion diario. La proyeccion hoy se ajusta MENSUALMENTE o cuando es necesario; se quiere que sea SEMANAL. | L12: Nada critico. El paso de mensual a semanal es un requisito, no una brecha.
A13: BR-09 | B13: Alta | C13: Brecha | D13: Que mide realmente el 6% | E13: P22: 'la desviacion de presupuesto de ventas vs la proyeccion normalmente esta 6% debajo del presupuesto'. | F13: Eso compara presupuesto contra proyeccion, no proyeccion contra corte real. Si se usa como linea base sin aclararlo, la meta del proyecto queda mal fijada desde el dia uno. | G13: Ese 6%, compara lo presupuestado contra lo proyectado, o contra lo que efectivamente se corto? Tienen el dato de proyectado contra cortado real de los ultimos meses? Aunque sea de una variedad. | H13: Director de produccion | I13: WhatsApp | J13: Cerrada | K13: CORREGIDO. El 6% compara lo presupuestado contra lo que efectivamente SE CORTO (no contra lo proyectado). El cliente confirmo que existe informacion historica de proyectado contra cortado real. | L13: Ninguna sobre el 6% en si. Pero abre BR-21: ese 6% y el +/-10% de meta no parecen medirse al mismo nivel de agregacion.
A14: BR-10 | B14: Critica | C14: Brecha | D14: Cierre de la sesion 1 sin hacer | E14: P42 a P45 sin respuesta: no se valido el resumen, no hay otros entrevistados, no hay datos de muestra, no hay segunda sesion. | F14: Sin datos reales y sin mas voces, todo el levantamiento descansa en la memoria de una sola persona. Es lo mas facil de recuperar y lo mas urgente. | G14: Ver la hoja 'Mensajes Listos', mensaje M1. Se resuelve hoy mismo con un correo. | H14: Director de produccion | I14: Correo hoy | J14: Cerrada | K14: La sesion 2 del 04-ago fue el cierre: se recorrieron las brechas, se valido el entendimiento y el cliente califico el contexto en 5/10 diciendo 'hay que volverla a hacer hasta conseguir un 9 con algo'. | L14: El punto de otros entrevistados NO se resolvio, se rechazo: 'me pregunta por mas personas a las que se pueda entrevistar, pero no, eso no'. Ver BR-25 como riesgo aceptado.
A15: BR-11 | B15: Media | C15: Brecha | D15: Catalogo de grados y calidades | E15: P19: explico bien el concepto (grado agrupa longitud, tamano, numero de flores, grosor, follaje) y que cada finca los define. No dio los de esta finca. | F15: Sin el catalogo real y sin el porcentaje historico por grado, la proyeccion solo puede dar un total de tallos, que comercialmente no sirve para vender. | G15: Me pasas la tabla de grados y calidades que usan ustedes? Y de una cosecha tipica, que porcentaje sale en cada grado? Sirve un estimado tuyo si no lo tienen medido. | H15: Director + poscosecha | I15: WhatsApp | J15: Abierta | K15: Se volvio a pedir. Respuesta: 'me pasas tablas de grados y calidades tambien - no, pero ya dentro del sistema'. Es decir, existe pero dentro del sistema actual, y no se entrego. | L15: El catalogo de grados de esta finca y el porcentaje historico que cae en cada grado por variedad. Sin esto la proyeccion solo da un total de tallos, que comercialmente no sirve.
... A29: BR-25 | B29: Alta | C29: Riesgo aceptado | D29: Todo descansa en una sola voz | E29: S2: 'me pregunta por mas personas a las que se pueda entrevistar, pero no, eso no'. S1 (P16): 'desde planeacion me dicen que debo plantar y que tanto'. | F29: El sistema sirve a planeacion, produccion, ventas, compras y gerencia, y solo se entrevisto al director de produccion. Planeacion, que es donde NACE la proyeccion, nunca se exploro. El cliente cerro la puerta, asi que no es una brecha que se pueda cerrar preguntando: es un riesgo que hay que dejar escrito y asumido. | G29: No insistir por ahora. Dejarlo registrado como supuesto en la hoja Pendientes y Riesgos de la plantilla, y reintentar via documentos: el plan de siembra que entrega planeacion habla por planeacion. | H29: Equipo | I29: Documentar | J29: Abierta | K29: El cliente rechazo ampliar la cobertura de entrevistados. | L29: Aceptar el riesgo por escrito y compensarlo con artefactos en vez de entrevistas.

Sheet Plan de Acercamiento
A1: Estrategias rapidas para cerrar las brechas
A2: Principio: no pidas otra sesion de 90 minutos. Fragmenta en piezas de 20 minutos, mensajes de una sola pregunta y peticiones de archivos. Actualizado el 05-ago-2026: la columna G dice que tactica ya se uso. El calendario de 10 dias de abajo se ejecuto parcialmente; lo que quedo pendiente esta en la hoja 'Estado tras Sesion 2'.
A4: # | B4: Tactica | C4: Cuando usarla | D4: Como se ejecuta | E4: Brechas que cierra | F4: Esfuerzo | G4: Estado al 05-ago-2026
A5: 1 | B5: Acta con preguntas embebidas | C5: Dentro de las primeras 48 h despues de la sesion. Es lo primero que debes hacer. | D5: Envia por correo el resumen de lo que entendiste, en 7 u 8 vinetas, y al final numera maximo 5 preguntas cortas. Responder por escrito le cuesta menos al cliente que agendar una reunion, y de paso recuperas el cierre que se perdio (P42 a P45). Truco: escribe el resumen con una o dos imprecisiones deliberadas y evidentes. La gente que no responde preguntas si corrige errores. | E5: BR-10, BR-17 | F5: 30 min | G5: HECHA - La sesion 2 cumplio esta funcion: se valido el entendimiento y se recupero el bloque de cierre.
A6: 2 | B6: Micro-reuniones tematicas de 20 a 30 min | C6: Para las brechas criticas que necesitan conversacion, no texto. | D6: Cuatro sesiones cortas en vez de una larga: (1) TI y sistema actual mas PowerBI; (2) taller del motor de proyeccion con el director; (3) ventas y planeacion; (4) calidad y Florverde. Agenda cada una con un asunto de una linea que diga exactamente que se decide ahi. Una reunion sin decision anunciada se cancela; una con decision anunciada se respeta. | E6: BR-01, BR-02, BR-03, BR-07, BR-16 | F6: 2 h en total | G6: PARCIAL - Se hizo una sesion larga en vez de cuatro cortas, y funciono. Faltan las de TI/sistema actual y la de ventas.
A7: 3 | B7: Reconstruir el calculo con un caso real | C7: Para BR-03, la brecha mas critica. No se resuelve preguntando 'como proyectas'. | D7: Sientate con el director y una sola cama real. Pide los numeros de esa cama: esquejes sembrados, fecha de siembra, tallos esperados, dia en que empezo el corte, cuantos dias duro, cuantos tallos por dia, cuanto se perdio. Con un caso completo tienes la formula; con tres, tienes el modelo. Llevalo en una hoja de calculo abierta y calcula frente a el: cuando vea un numero que no cuadra, va a corregirte solo. | E7: BR-03, BR-04, BR-09 | F7: 60 min | G7: PENDIENTE - Lo mas importante que queda. Se avanzo en la estructura del calculo pero sin una cama real con numeros. Ver BR-23.
A8: 4 | B8: Acompanamiento en campo (shadowing) | C8: Cuando el cliente dice 'todo esta sistematizado' y sospechas que no. | D8: Pide ir un dia de siembra y seguir al supervisor durante dos horas, sin preguntar nada, solo mirando y fotografiando los formatos. Dos horas ahi valen mas que tres entrevistas: ves la letra, los tachones, el orden real de los pasos y en que momento se pierde el dato. Tambien resuelves la conectividad caminando con el celular en la mano. | E8: BR-05, BR-06, BR-14 | F8: 2 h, alto valor | G8: PENDIENTE - No se ha ido a campo. Sigue siendo la tactica de mejor relacion esfuerzo/resultado que queda sin usar.
A9: 5 | B9: Pedir artefactos en vez de explicaciones | C9: Siempre. Es la tactica de mejor relacion esfuerzo/resultado. | D9: Los documentos no se cansan ni olvidan. Pide: los formatos en papel llenos de esta semana, un export del sistema actual, captura del tablero de PowerBI, el presupuesto de produccion del ano, la tabla de grados, y los formatos de Florverde. Un archivo real te contesta veinte preguntas que nunca hiciste. | E9: BR-01, BR-02, BR-11, BR-15 | F9: 10 min | G9: PENDIENTE - Se pidieron los documentos dos veces y no ha llegado ninguno. ESTE ES EL BLOQUEO REAL DEL PROYECTO.
A10: 6 | B10: Cerrar con opciones, no con preguntas abiertas | C10: Cuando el cliente no supo responder, como paso en P17 y P39. | D10: Si no entendio la pregunta, el problema es la pregunta. Reformula ofreciendo dos o tres opciones concretas y deja abierta la salida: 'es A, B, o ninguna de las dos?'. Responder eligiendo cuesta mucho menos que responder explicando, y si ninguna le cuadra, corregirte le sale natural. | E10: BR-04, BR-08, BR-12 | F10: 0 | G10: HECHA - Se uso en la sesion 2 y funciono: el cruce con pedidos se cerro ofreciendo opcion A o B, y el cliente eligio A de inmediato.
A11: 7 | B11: Validar con un prototipo, no con un documento | C11: Para la segunda sesion, cuando ya tengas las brechas criticas cerradas. | D11: Arma una pantalla falsa o un Excel simulado con datos inventados pero realistas de esta finca y ponlo enfrente. La gente corrige mucho mejor de lo que especifica. En 20 minutos vas a sacar mas requisitos que en toda la primera entrevista. | E11: Validacion general | F11: 3 h de armado | G11: PENDIENTE - Es el siguiente paso natural una vez lleguen los documentos.
A12: 8 | B12: Una pregunta por mensaje en WhatsApp | C12: Para todo lo que no requiera conversacion. | D12: Nunca mandes tres preguntas juntas: te contestan la ultima. Una pregunta por mensaje, cerrada, con contexto minimo de una linea, y siempre ofreciendo la salida facil ('si no lo tienes a la mano, un estimado tuyo me sirve'). Manda como maximo dos al dia y respeta el horario laboral. | E12: La mayoria de las medias | F12: 2 min c/u | G12: PARCIAL - Se uso poco. Sigue siendo el canal correcto para BR-21, BR-22, BR-11 y BR-14.
A13: 9 | B13: Confirmar entendiendo al reves | C13: Para reglas de negocio que creiste entender. | D13: En vez de preguntar, afirma lo que entendiste y pide correccion: 'Yo entendi que cuando una cama se erradica, lo que ya estaba vendido de ahi se compra a terceros. Es asi o me falta algo?'. Corregir es mas rapido y mas comodo que explicar desde cero, y ademas revela los matices. | E13: BR-18, reglas en general | F13: 0 | G13: HECHA - Se uso mucho en la sesion 2 y ahi se resolvieron las cuatro contradicciones de la sesion 1.
A14: 10 | B14: Escalar a gerencia con el numero del dolor | C14: Si el cliente deja de responder o no consigues acceso a otras areas. | D14: Ya tienes las cifras: 8 dias de latencia, 4 horas semanales de digitacion, 2% de error. Presentalas a gerencia como costo actual y pide acceso a las otras areas para poder cuantificar el resto. Un numero abre puertas que un correo de seguimiento no abre. | E14: BR-10, BR-16 | F14: 20 min | G14: SIN USAR - No ha hecho falta: el cliente responde. Guardarla por si se enfria.
B16: Orden sugerido para los proximos 10 dias
B17: Dia 1 | C17: Enviar el acta con preguntas embebidas (mensaje M1). Es lo unico verdaderamente urgente.
B18: Dia 1 | C18: Mandar por WhatsApp M2 (contradiccion de conectividad) y M3 (foto de los formatos).
B19: Dia 2-3 | C19: Agendar la micro-reunion de sistema actual y PowerBI. Es la brecha que mas puede cambiar el proyecto.
B20: Dia 3-4 | C20: Taller de 60 min para reconstruir el calculo con una cama real.
B21: Dia 5 | C21: Visita de campo de 2 horas en un dia de siembra.
B22: Dia 6-7 | C22: Micro-reunion con ventas: alcance del cruce con pedidos y costo del error.
B23: Dia 8-9 | C23: Armar el prototipo con datos simulados de la finca.
B24: Dia 10 | C24: Sesion de validacion de 45 min sobre el prototipo. Recien ahi puedes estimar.

Sheet Mensajes Listos
A1: Mensajes listos para enviar
A2: Copiar, ajustar nombres y enviar. Actualizado el 05-ago-2026: la columna G dice cuales ya se resolvieron en la sesion 2 y cuales siguen vigentes. M13 a M15 son nuevos, salidos del analisis de la sesion 2. Recuerda la convencion de WhatsApp: nada de asteriscos ni guiones al inicio de linea.
A4: ID | B4: Canal | C4: Para | D4: Cuando | E4: Texto listo para copiar | F4: Cierra | G4: Estado al 05-ago-2026
A5: M1 | B5: Correo | C5: Director de produccion | D5: Hoy mismo | E5: Asunto: Resumen de nuestra conversacion + 5 dudas cortas Hola [nombre], Gracias por el tiempo del [dia]. Te dejo por escrito lo que entendi, para que me corrijas si algo quedo torcido: 1. La finca son 15 ha organizadas en bloques, naves y camas, con 9 variedades activas y ciclos de 3 a 5 meses. 2. Proyectan a un ano o ano y medio para armar el presupuesto, y despues lo van ajustando contra la realidad. 3. El ajuste lo haces yendo fisicamente a la cama: subes o bajas un porcentaje de produccion y corres la fecha de corte unos dias. 4. Hoy se registra basicamente la siembra. El supervisor llena formatos a mano (1 hora al dia) y un practicante los digita (4 horas a la semana). 5. Planeacion y gerencia terminan viendo el dato 8 dias despues, con un error cercano al 2%. 6. Los reportes salen hoy en PowerBI, semanalmente. 7. El foco del proyecto, en tus palabras, es la captura de datos de siembra y produccion. Cinco dudas cortas, con responder en una linea cada una me sirve: a) Cuando dices 'el sistema', a cual te refieres? Como se llama y quien lo administra? b) El PowerBI actual se queda y nosotros le entregamos los datos, o quieren informes nuevos dentro del sistema? c) Con quien mas deberia hablar de planeacion, ventas y calidad? Me los presentas? d) Me puedes compartir el presupuesto de produccion de este ano y los formatos que llena el supervisor? e) Te queda bien una sesion de 45 minutos la proxima semana para mostrarte un boceto? Quedo atento, [tu nombre] | F5: BR-10, BR-01, BR-02, BR-17 | G5: YA NO HACE FALTA - La sesion 2 cubrio el resumen y la validacion.
A6: M2 | B6: WhatsApp | C6: Supervisor o director | D6: Hoy | E6: Hola [nombre], una duda corta que me quedo del cultivo: me dijiste que alla no hay senal ni wifi, pero tambien que el formato de plagas se llena en el celular y sube al sistema. En que momento sube? Lo llenan en la cama y sube despues, o lo llenan ya afuera? Es para saber si la app tiene que funcionar sin internet. | F6: BR-05 | G6: RESUELTO - La app de plagas es local en el celular y sube despues. Es offline-first, no habia contradiccion.
A7: M3 | B7: WhatsApp | C7: Supervisor de siembra | D7: Hoy | E7: Hola [nombre], me harias un favor grande: cuando llenes los formatos de esta semana, me mandas una foto de como quedan llenos? Tal cual, con la letra y los tachones. No es para revisarte nada, es para disenar la pantalla parecida a lo que ya usas y que no te cambie la rutina. | F7: BR-06 | G7: SIGUE VIGENTE - La foto de los formatos nunca llego. Reenviar.
A8: M4 | B8: WhatsApp | C8: Director de produccion | D8: Dia 1-2 | E8: Hola [nombre], creo que la pregunta de las etapas te la hice enredada. Te la pongo mas simple con un ejemplo: si hoy voy y veo una cama en desbotone, en cuantos dias mas o menos empieza el corte? Y si la veo en boton color? Un estimado tuyo me sirve, no necesito exactitud. | F8: BR-04 | G8: RESUELTO - Desbotone a corte 3 semanas, boton color a corte ~12 dias.
A9: M5 | B9: WhatsApp | C9: Director de produccion | D9: Dia 2 | E9: Hola [nombre], sobre el 6% de desviacion que me comentaste: ese numero compara el presupuesto contra la proyeccion, o contra lo que efectivamente se corto? Es que son cosas distintas y quiero no confundirlas en el documento. | F9: BR-09 | G9: RESUELTO - El 6% compara presupuestado contra cortado real. Pero abrio BR-21, ver mensaje M13.
A10: M6 | B10: WhatsApp | C10: Director de produccion | D10: Dia 2-3 | E10: Hola [nombre], necesito cerrar un punto de alcance y te lo pongo como opciones para que sea rapido: A) El sistema muestra solo cuanta flor vamos a tener. B) Ademas muestra cuanta ya esta comprometida y con que cliente. Si es B, la dejamos en la primera fase o la pasamos a una segunda? Solo dime A, B1 o B2 y yo lo documento. | F10: BR-07 | G10: RESUELTO - El cliente eligio A: el sistema solo muestra que flor se va a producir.
A11: M7 | B11: WhatsApp | C11: Director de produccion | D11: Dia 3 | E11: Hola [nombre], te pido 60 minutos para una sola cosa: reconstruir contigo el calculo de la proyeccion con un caso real. Escoge una cama cualquiera y llevamos sus numeros (esquejes sembrados, fecha, cuanto esperabas, cuando empezo el corte, cuanto duro y cuanto salio). Con un ejemplo completo entiendo la logica y no te vuelvo a preguntar lo mismo de diez formas distintas. | F11: BR-03 | G11: SIGUE VIGENTE - El taller de la cama real no se ha hecho. Es lo que cierra BR-23.
A12: M8 | B12: WhatsApp | C12: Director de produccion | D12: Dia 4 | E12: Hola [nombre], podria acompanar al supervisor un dia de siembra, unas dos horas? Voy solo a mirar, sin interrumpir. Ver el proceso en vivo me ahorra a mi como tres reuniones y a ti todas mis preguntas. | F12: BR-05, BR-06, BR-14 | G12: SIGUE VIGENTE - La visita de campo no se ha hecho.
A13: M9 | B13: WhatsApp | C13: Director de produccion | D13: Dia 4-5 | E13: Hola [nombre], tres datos rapidos cuando puedas, un estimado me sirve: 1) Cuantos registros de siembra o produccion se llenan en un dia pico? 2) Cuantas personas estarian usando el sistema al mismo tiempo? 3) Los supervisores usan celular propio o de la finca? | F13: BR-13, BR-14 | G13: PARCIAL - Ya se sabe: 3 capturan, ~12 usan, ~20 consultan. Falta el punto 1 (registros en dia pico) y el punto 3 (celulares).
A14: M10 | B14: WhatsApp | C14: Director de produccion | D14: Cuando aplique | E14: Hola [nombre], quiero confirmar que entendi bien esto: cuando se decide erradicar una cama a mitad de ciclo porque no hay ventas o viene enferma, lo que ya estaba vendido de ahi se cubre comprando a terceros. Es asi o me esta faltando un paso? | F14: BR-18 | G14: RESUELTO - Se erradica, se digita, el sistema resta, y lo vendido se cancela o se compra a terceros. Pasa semanalmente.
A15: M11 | B15: Correo | C15: Jefe de calidad | D15: Dia 3 | E15: Asunto: Registros que exige Florverde Hola [nombre], estoy levantando los requisitos del sistema de produccion con [nombre del director]. Me puedes compartir los formatos o el listado de registros que exige Florverde, y cada cuanto los auditan? Quiero asegurarme de que el sistema los genere desde el inicio y no tocar nada dos veces. Gracias, [tu nombre] | F15: BR-15 | G15: YA NO APLICA - Florverde quedo fuera del alcance por decision del cliente.
... A19: M15 | B19: WhatsApp | C19: Director de produccion | D19: Dia 1-2 | E19: Hola [nombre], dos cosas del calculo de la proyeccion y con eso ya lo tengo completo. 1) El porcentaje de productividad por variedad, ese 90% o 80% que me explicaste, de donde lo sacan? Es un historico de ustedes, una tabla del ingeniero o viene en la ficha del proveedor de esquejes? 2) En los 7 dias que dura el corte de una cama, sale parejo cada dia o hay dias fuertes? Si me pasas los numeros de una cama real yo lo saco de ahi y no te vuelvo a preguntar. | F19: BR-23 | G19: NUEVO - creado tras la sesion 2. Enviar.
