Workbook

Sheet Instructivo
A1: FlorLogic — Preguntas de caracterización por atributo de calidad
A2: Versión 2 · 21-ago-2026 · insumo previo a los escenarios de calidad (ESC-nnn). Reemplaza la v1.
A4: Qué cambió frente a la v1
A5: Seguridad de funcionamiento deja de ser un atributo propio: queda absorbida por Confiabilidad, que ahora cubre también la pérdida y el daño de información ante fallos. Sus 15 preguntas se conservan íntegras, renumeradas CNF-43 a CNF-57.
A6: Trazabilidad pasa a llamarse Capacidad para ser Auditado, entendida como trazabilidad + cumplimiento, según quedó definida en el nuevo mini QAW. Las 18 preguntas anteriores se conservan como el bloque de trazabilidad y se suman 14 nuevas de cumplimiento y evidencia ante terceros (marcadas en verde en la hoja Preguntas).
A7: Los atributos van en el orden del nuevo mini QAW: menor puntuación = mayor prioridad.
A8: El prefijo de Escalabilidad cambia de ESC- a ESL-, para no colisionar con la numeración ESC-nnn de los escenarios de calidad.
A9: Total: 262 preguntas sobre 13 atributos, más 3 de cierre.
A11: Cómo se diligencia
A12: 1. En la hoja «Preguntas», responder la columna Respuesta con Sí, No o N/A (lista desplegable). Las celdas amarillas son las únicas que se editan.
A13: 2. Si la respuesta necesita matiz, va en Nota — nunca dentro de la pregunta.
A14: 3. La columna Escenario se llena después de la sesión con el ID del escenario que se derive (ESC-001, ESC-002...). Una pregunta puede quedar sin escenario.
... A24: Ejemplo de fila diligenciada
A25: Identificador | B25: Atributo | C25: Bloque | D25: Pregunta | E25: Respuesta | F25: Nota
A26: CNF-04 | B26: Confiabilidad | C26: Verificación en el momento de la captura | D26: ¿Se necesita verificar que la información sea correcta de manera que se agrupe la información por cama? | E26: Sí | F26: Hasta cama sí; por bloque ya no lo revisa nadie. El corte queda entre CNF-04 y CNF-05.

Sheet Preguntas
A1: Identificador | B1: Atributo | C1: Bloque | D1: Pregunta | E1: Respuesta | F1: Nota | G1: Escenario
A2: CNF-01 | B2: Confiabilidad | C2: Verificación en el momento de la captura | D2: ¿Se necesita verificar que la información sea correcta de manera individual con cada dato tomado?
A3: CNF-02 | B3: Confiabilidad | C3: Verificación en el momento de la captura | D3: ¿Se necesita verificar que la información sea correcta de manera que se agrupe la información por variedad?
A4: CNF-03 | B4: Confiabilidad | C4: Verificación en el momento de la captura | D4: ¿Se necesita verificar que la información sea correcta de manera que se agrupe la información por sección de la cama?
A5: CNF-04 | B5: Confiabilidad | C5: Verificación en el momento de la captura | D5: ¿Se necesita verificar que la información sea correcta de manera que se agrupe la información por cama?
A6: CNF-05 | B6: Confiabilidad | C6: Verificación en el momento de la captura | D6: ¿Se necesita verificar que la información sea correcta de manera que se agrupe la información por bloque?
A7: CNF-06 | B7: Confiabilidad | C7: Verificación en el momento de la captura | D7: ¿Se necesita verificar que la información sea correcta de manera que se agrupe la información por finca y por jornada completa?
A8: CNF-07 | B8: Confiabilidad | C8: Verificación en el momento de la captura | D8: ¿Se necesita una confirmación final que muestre todo lo capturado antes de darlo por guardado?
A9: CNF-08 | B9: Confiabilidad | C9: Verificación en el momento de la captura | D9: ¿Se necesita que el sistema impida cerrar la captura de una cama si quedaron campos sin diligenciar?
A10: CNF-09 | B10: Confiabilidad | C10: Verificación en el momento de la captura | D10: ¿Se necesita que el sistema permita guardar una captura incompleta y marcarla como pendiente?
A11: CNF-10 | B11: Confiabilidad | C11: Reglas de validación | D11: ¿Se necesita que el sistema rechace un dato cuando está fuera del rango posible (por ejemplo, más tallos que plantas sembradas)?
A12: CNF-11 | B12: Confiabilidad | C12: Reglas de validación | D12: ¿Se necesita que el sistema advierta, sin bloquear, cuando un dato se aleja mucho de lo que se ha capturado históricamente en esa misma cama?
A13: CNF-12 | B13: Confiabilidad | C13: Reglas de validación | D13: ¿Se necesita que el sistema muestre siempre el motivo por el cual rechazó un dato?
... A58: CNF-57 | B58: Confiabilidad | C58: Comportamiento ante fallos y pérdida de información | D58: ¿Se necesita que la aplicación avise cuando el almacenamiento del dispositivo está por llenarse?
A59: DSP-01 | B59: Disponibilidad | D59: ¿Se necesita capturar información en el área de cultivo sin ninguna conexión de datos?
A60: DSP-02 | B60: Disponibilidad | D60: ¿Se necesita capturar durante una jornada completa sin sincronizar en ningún momento?
A61: DSP-03 | B61: Disponibilidad | D61: ¿Se necesita capturar durante tres días seguidos sin sincronizar?
A62: DSP-04 | B62: Disponibilidad | D62: ¿Se necesita capturar durante una semana seguida sin sincronizar?
A63: DSP-05 | B63: Disponibilidad | D63: ¿Se necesita capturar durante más de quince días sin sincronizar?
A64: DSP-06 | B64: Disponibilidad | D64: ¿Se necesita poder consultar la información ya sincronizada aunque en ese momento no haya conexión?
A65: DSP-07 | B65: Disponibilidad | D65: ¿Se necesita poder consultar la información desde la web aunque la aplicación de captura esté fuera de servicio?
A66: DSP-08 | B66: Disponibilidad | D66: ¿Se necesita que la captura siga funcionando aunque el servicio en la nube esté caído?
A67: DSP-09 | B67: Disponibilidad | D67: ¿Se necesita que exista un horario del día en el que el sistema no pueda estar fuera de servicio bajo ninguna circunstancia?
A68: DSP-10 | B68: Disponibilidad | D68: ¿Se necesita que el sistema esté disponible los siete días de la semana?
A69: DSP-11 | B69: Disponibilidad | D69: ¿Se necesita que el sistema esté disponible las veinticuatro horas del día?
A70: DSP-12 | B70: Disponibilidad | D70: ¿Se necesita que exista un periodo del año (temporada alta) con una exigencia de disponibilidad mayor que el resto?
... A99: RND-21 | B99: Rendimiento | D99: ¿Se necesita que el rendimiento se mantenga igual en temporada alta que en el resto del año?
A100: AUD-01 | B100: Capacidad para ser Auditado | C100: Trazabilidad de la información | D100: ¿Se necesita saber quién capturó cada dato?
A101: AUD-02 | B101: Capacidad para ser Auditado | C101: Trazabilidad de la información | D101: ¿Se necesita saber la fecha y la hora exactas en que se capturó cada dato?
A102: AUD-03 | B102: Capacidad para ser Auditado | C102: Trazabilidad de la información | D102: ¿Se necesita distinguir la hora en que se capturó de la hora en que se sincronizó?
A103: AUD-04 | B103: Capacidad para ser Auditado | C103: Trazabilidad de la información | D103: ¿Se necesita saber desde qué dispositivo se capturó cada dato?
A104: AUD-05 | B104: Capacidad para ser Auditado | C104: Trazabilidad de la información | D104: ¿Se necesita saber en qué lugar físico se encontraba el dispositivo al capturar?
A105: AUD-06 | B105: Capacidad para ser Auditado | C105: Trazabilidad de la información | D105: ¿Se necesita conservar todas las versiones anteriores de un dato modificado, y no solo la última?
A106: AUD-07 | B106: Capacidad para ser Auditado | C106: Trazabilidad de la información | D106: ¿Se necesita saber quién hizo cada modificación y por qué motivo?
A107: AUD-08 | B107: Capacidad para ser Auditado | C107: Trazabilidad de la información | D107: ¿Se necesita poder ver la historia completa de una cama desde la siembra hasta la erradicación?
A108: AUD-09 | B108: Capacidad para ser Auditado | C108: Trazabilidad de la información | D108: ¿Se necesita poder ver la historia completa de un lote a través de varias camas?
A109: AUD-10 | B109: Capacidad para ser Auditado | C109: Trazabilidad de la información | D109: ¿Se necesita poder ver la historia completa de una variedad a través de varios ciclos?
A110: AUD-11 | B110: Capacidad para ser Auditado | C110: Trazabilidad de la información | D110: ¿Se necesita poder llegar, desde una cifra de un reporte, hasta los datos individuales que la componen?
A111: AUD-12 | B111: Capacidad para ser Auditado | C111: Trazabilidad de la información | D111: ¿Se necesita registrar también quién consultó o exportó la información, y no solo quién la modificó?
... A131: AUD-32 | B131: Capacidad para ser Auditado | C131: Cumplimiento y evidencia ante terceros | D131: ¿Se necesita poder demostrar con información del propio sistema el cumplimiento de un compromiso adquirido con un tercero?
...

Sheet Resumen
A1: Resumen de respuestas por atributo
A2: Se calcula solo a partir de la hoja «Preguntas». No escribir en esta hoja. Los atributos van en el orden del nuevo mini QAW.
A4: Prioridad | B4: Atributo | C4: Qué mide | D4: Mini QAW | E4: Preguntas | F4: Sí | G4: No | H4: N/A | I4: Sin responder | J4: % respondido
A5: 1 | B5: Confiabilidad | C5: Que la información sea correcta, que el sistema no entregue resultados equivocados y que nada se pierda cuando algo falla. Absorbe lo que antes se llamaba Seguridad de funcionamiento. | D5: ='Ranking mini QAW'!$F5 -> 3 | E5: =COUNTIF(Preguntas!$B$2:$B$263,$B5) -> 57 | F5: =COUNTIFS(Preguntas!$B$2:$B$263,$B5,Preguntas!$E$2:$E$263,"Sí") -> 0 | G5: =COUNTIFS(Preguntas!$B$2:$B$263,$B5,Preguntas!$E$2:$E$263,"No") -> 0 | H5: =COUNTIFS(Preguntas!$B$2:$B$263,$B5,Preguntas!$E$2:$E$263,"N/A") -> 0 | I5: =$E5-SUM($F5:$H5) -> 57 | J5: =IFERROR(SUM($F5:$H5)/$E5,0) -> 0
A6: 2 | B6: Disponibilidad | C6: Que se pueda usar cuando se necesita, incluso sin conexión o con fallos. | D6: ='Ranking mini QAW'!$F6 -> 11 | E6: =COUNTIF(Preguntas!$B$2:$B$263,$B6) -> 20 | F6: =COUNTIFS(Preguntas!$B$2:$B$263,$B6,Preguntas!$E$2:$E$263,"Sí") -> 0 | G6: =COUNTIFS(Preguntas!$B$2:$B$263,$B6,Preguntas!$E$2:$E$263,"No") -> 0 | H6: =COUNTIFS(Preguntas!$B$2:$B$263,$B6,Preguntas!$E$2:$E$263,"N/A") -> 0 | I6: =$E6-SUM($F6:$H6) -> 20 | J6: =IFERROR(SUM($F6:$H6)/$E6,0) -> 0
A7: 3 | B7: Rendimiento | C7: Que responda con la rapidez que exige el ritmo del campo. | D7: ='Ranking mini QAW'!$F7 -> 17 | E7: =COUNTIF(Preguntas!$B$2:$B$263,$B7) -> 21 | F7: =COUNTIFS(Preguntas!$B$2:$B$263,$B7,Preguntas!$E$2:$E$263,"Sí") -> 0 | G7: =COUNTIFS(Preguntas!$B$2:$B$263,$B7,Preguntas!$E$2:$E$263,"No") -> 0 | H7: =COUNTIFS(Preguntas!$B$2:$B$263,$B7,Preguntas!$E$2:$E$263,"N/A") -> 0 | I7: =$E7-SUM($F7:$H7) -> 21 | J7: =IFERROR(SUM($F7:$H7)/$E7,0) -> 0
A8: 4 | B8: Capacidad para ser Auditado | C8: Que se pueda reconstruir quién hizo qué y con qué información, y demostrarlo ante quien lo exija. Mezcla trazabilidad y cumplimiento. | D8: ='Ranking mini QAW'!$F8 -> 17 | E8: =COUNTIF(Preguntas!$B$2:$B$263,$B8) -> 32 | F8: =COUNTIFS(Preguntas!$B$2:$B$263,$B8,Preguntas!$E$2:$E$263,"Sí") -> 0 | G8: =COUNTIFS(Preguntas!$B$2:$B$263,$B8,Preguntas!$E$2:$E$263,"No") -> 0 | H8: =COUNTIFS(Preguntas!$B$2:$B$263,$B8,Preguntas!$E$2:$E$263,"N/A") -> 0 | I8: =$E8-SUM($F8:$H8) -> 32 | J8: =IFERROR(SUM($F8:$H8)/$E8,0) -> 0
A9: 5 | B9: Capacidad | C9: Cuánta información tiene que soportar y por cuánto tiempo. | D9: ='Ranking mini QAW'!$F9 -> 19 | E9: =COUNTIF(Preguntas!$B$2:$B$263,$B9) -> 15 | F9: =COUNTIFS(Preguntas!$B$2:$B$263,$B9,Preguntas!$E$2:$E$263,"Sí") -> 0 | G9: =COUNTIFS(Preguntas!$B$2:$B$263,$B9,Preguntas!$E$2:$E$263,"No") -> 0 | H9: =COUNTIFS(Preguntas!$B$2:$B$263,$B9,Preguntas!$E$2:$E$263,"N/A") -> 0 | I9: =$E9-SUM($F9:$H9) -> 15 | J9: =IFERROR(SUM($F9:$H9)/$E9,0) -> 0
A10: 6 | B10: Capacidad para ser Administrado | C10: Que el día a día del sistema se pueda manejar desde adentro, sin desarrollo. | D10: ='Ranking mini QAW'!$F10 -> 23 | E10: =COUNTIF(Preguntas!$B$2:$B$263,$B10) -> 16 | F10: =COUNTIFS(Preguntas!$B$2:$B$263,$B10,Preguntas!$E$2:$E$263,"Sí") -> 0 | G10: =COUNTIFS(Preguntas!$B$2:$B$263,$B10,Preguntas!$E$2:$E$263,"No") -> 0 | H10: =COUNTIFS(Preguntas!$B$2:$B$263,$B10,Preguntas!$E$2:$E$263,"N/A") -> 0 | I10: =$E10-SUM($F10:$H10) -> 16 | J10: =IFERROR(SUM($F10:$H10)/$E10,0) -> 0
A11: 7 | B11: Experiencia de Usuario | C11: Que capturar sea más fácil que el papel, en las condiciones del cultivo. | D11: ='Ranking mini QAW'!$F11 -> 24 | E11: =COUNTIF(Preguntas!$B$2:$B$263,$B11) -> 18 | F11: =COUNTIFS(Preguntas!$B$2:$B$263,$B11,Preguntas!$E$2:$E$263,"Sí") -> 0 | G11: =COUNTIFS(Preguntas!$B$2:$B$263,$B11,Preguntas!$E$2:$E$263,"No") -> 0 | H11: =COUNTIFS(Preguntas!$B$2:$B$263,$B11,Preguntas!$E$2:$E$263,"N/A") -> 0 | I11: =$E11-SUM($F11:$H11) -> 18 | J11: =IFERROR(SUM($F11:$H11)/$E11,0) -> 0
A12: 8 | B12: Seguridad | C12: Que la información no llegue a quien no debe. | D12: ='Ranking mini QAW'!$F12 -> 24 | E12: =COUNTIF(Preguntas!$B$2:$B$263,$B12) -> 19 | F12: =COUNTIFS(Preguntas!$B$2:$B$263,$B12,Preguntas!$E$2:$E$263,"Sí") -> 0 | G12: =COUNTIFS(Preguntas!$B$2:$B$263,$B12,Preguntas!$E$2:$E$263,"No") -> 0 | H12: =COUNTIFS(Preguntas!$B$2:$B$263,$B12,Preguntas!$E$2:$E$263,"N/A") -> 0 | I12: =$E12-SUM($F12:$H12) -> 19 | J12: =IFERROR(SUM($F12:$H12)/$E12,0) -> 0
A13: 9 | B13: Interoperatividad | C13: Qué tanto tiene que hablar con lo que ya existe. | D13: ='Ranking mini QAW'!$F13 -> 25 | E13: =COUNTIF(Preguntas!$B$2:$B$263,$B13) -> 13 | F13: =COUNTIFS(Preguntas!$B$2:$B$263,$B13,Preguntas!$E$2:$E$263,"Sí") -> 0 | G13: =COUNTIFS(Preguntas!$B$2:$B$263,$B13,Preguntas!$E$2:$E$263,"No") -> 0 | H13: =COUNTIFS(Preguntas!$B$2:$B$263,$B13,Preguntas!$E$2:$E$263,"N/A") -> 0 | I13: =$E13-SUM($F13:$H13) -> 13 | J13: =IFERROR(SUM($F13:$H13)/$E13,0) -> 0
A14: 10 | B14: Escalabilidad | C14: Que crecer no obligue a rehacerlo. | D14: ='Ranking mini QAW'!$F14 -> 25 | E14: =COUNTIF(Preguntas!$B$2:$B$263,$B14) -> 11 | F14: =COUNTIFS(Preguntas!$B$2:$B$263,$B14,Preguntas!$E$2:$E$263,"Sí") -> 0 | G14: =COUNTIFS(Preguntas!$B$2:$B$263,$B14,Preguntas!$E$2:$E$263,"No") -> 0 | H14: =COUNTIFS(Preguntas!$B$2:$B$263,$B14,Preguntas!$E$2:$E$263,"N/A") -> 0 | I14: =$E14-SUM($F14:$H14) -> 11 | J14: =IFERROR(SUM($F14:$H14)/$E14,0) -> 0
A15: 11 | B15: Capacidad para ser Soportado | C15: Qué pasa cuando algo falla y hay que resolverlo. | D15: ='Ranking mini QAW'!$F15 -> 27 | E15: =COUNTIF(Preguntas!$B$2:$B$263,$B15) -> 13 | F15: =COUNTIFS(Preguntas!$B$2:$B$263,$B15,Preguntas!$E$2:$E$263,"Sí") -> 0 | G15: =COUNTIFS(Preguntas!$B$2:$B$263,$B15,Preguntas!$E$2:$E$263,"No") -> 0 | H15: =COUNTIFS(Preguntas!$B$2:$B$263,$B15,Preguntas!$E$2:$E$263,"N/A") -> 0 | I15: =$E15-SUM($F15:$H15) -> 13 | J15: =IFERROR(SUM($F15:$H15)/$E15,0) -> 0
A16: 12 | B16: Portabilidad | C16: Dónde y sobre qué tiene que poder funcionar. | D16: ='Ranking mini QAW'!$F16 -> 28 | E16: =COUNTIF(Preguntas!$B$2:$B$263,$B16) -> 13 | F16: =COUNTIFS(Preguntas!$B$2:$B$263,$B16,Preguntas!$E$2:$E$263,"Sí") -> 0 | G16: =COUNTIFS(Preguntas!$B$2:$B$263,$B16,Preguntas!$E$2:$E$263,"No") -> 0 | H16: =COUNTIFS(Preguntas!$B$2:$B$263,$B16,Preguntas!$E$2:$E$263,"N/A") -> 0 | I16: =$E16-SUM($F16:$H16) -> 13 | J16: =IFERROR(SUM($F16:$H16)/$E16,0) -> 0
A17: 13 | B17: Accesibilidad | C17: Que todo el que deba usarlo pueda usarlo. | D17: ='Ranking mini QAW'!$F17 -> 30 | E17: =COUNTIF(Preguntas!$B$2:$B$263,$B17) -> 11 | F17: =COUNTIFS(Preguntas!$B$2:$B$263,$B17,Preguntas!$E$2:$E$263,"Sí") -> 0 | G17: =COUNTIFS(Preguntas!$B$2:$B$263,$B17,Preguntas!$E$2:$E$263,"No") -> 0 | H17: =COUNTIFS(Preguntas!$B$2:$B$263,$B17,Preguntas!$E$2:$E$263,"N/A") -> 0 | I17: =$E17-SUM($F17:$H17) -> 11 | J17: =IFERROR(SUM($F17:$H17)/$E17,0) -> 0
B18: Cierre de la sesión | C18: Preguntas que ordenan todo lo anterior y rompen los empates del ranking. | E18: =COUNTIF(Preguntas!$B$2:$B$263,$B18) -> 3 | F18: =COUNTIFS(Preguntas!$B$2:$B$263,$B18,Preguntas!$E$2:$E$263,"Sí") -> 0 | G18: =COUNTIFS(Preguntas!$B$2:$B$263,$B18,Preguntas!$E$2:$E$263,"No") -> 0 | H18: =COUNTIFS(Preguntas!$B$2:$B$263,$B18,Preguntas!$E$2:$E$263,"N/A") -> 0 | I18: =$E18-SUM($F18:$H18) -> 3 | J18: =IFERROR(SUM($F18:$H18)/$E18,0) -> 0
B19: TOTAL | E19: =SUM(E5:E18) -> 262 | F19: =SUM(F5:F18) -> 0 | G19: =SUM(G5:G18) -> 0 | H19: =SUM(H5:H18) -> 0 | I19: =SUM(I5:I18) -> 262 | J19: =IFERROR(SUM($F19:$H19)/$E19,0) -> 0
A21: Lectura: el patrón de síes de esta hoja funciona como un ranking hecho con evidencia, no con una encuesta de ordenamiento. Sirve para romper los tres empates del mini QAW (Rendimiento/Auditado 17, UX/Seguridad 24, Interoperatividad/Escalabilidad 25).

Sheet Ranking mini QAW
A1: Ranking de atributos — nuevo mini QAW
A2: Puntuación por actor. Menor puntuación = mayor prioridad. Total y porcentaje se calculan solos.
A4: Prioridad | B4: Atributo | C4: Supervisor de campo | D4: Gerente de producción | E4: Administrador del sistema | F4: Total | G4: Porcentaje
A5: 1 | B5: Confiabilidad | C5: 1 | D5: 1 | E5: 1 | F5: =SUM(C5:E5) -> 3 | G5: =IFERROR($F5/$F$18,0) -> 0.010989011
A6: 2 | B6: Disponibilidad | C6: 2 | D6: 2 | E6: 7 | F6: =SUM(C6:E6) -> 11 | G6: =IFERROR($F6/$F$18,0) -> 0.04029304
A7: 3 | B7: Rendimiento | C7: 3 | D7: 5 | E7: 9 | F7: =SUM(C7:E7) -> 17 | G7: =IFERROR($F7/$F$18,0) -> 0.062271062
A8: 4 | B8: Capacidad para ser Auditado | C8: 9 | D8: 4 | E8: 4 | F8: =SUM(C8:E8) -> 17 | G8: =IFERROR($F8/$F$18,0) -> 0.062271062
A9: 5 | B9: Capacidad | C9: 11 | D9: 3 | E9: 5 | F9: =SUM(C9:E9) -> 19 | G9: =IFERROR($F9/$F$18,0) -> 0.06959707
A10: 6 | B10: Capacidad para ser Administrado | C10: 13 | D10: 7 | E10: 3 | F10: =SUM(C10:E10) -> 23 | G10: =IFERROR($F10/$F$18,0) -> 0.084249084
A11: 7 | B11: Experiencia de Usuario | C11: 6 | D11: 6 | E11: 12 | F11: =SUM(C11:E11) -> 24 | G11: =IFERROR($F11/$F$18,0) -> 0.087912088
A12: 8 | B12: Seguridad | C12: 10 | D12: 8 | E12: 6 | F12: =SUM(C12:E12) -> 24 | G12: =IFERROR($F12/$F$18,0) -> 0.087912088
A13: 9 | B13: Interoperatividad | C13: 5 | D13: 10 | E13: 10 | F13: =SUM(C13:E13) -> 25 | G13: =IFERROR($F13/$F$18,0) -> 0.091575092
A14: 10 | B14: Escalabilidad | C14: 8 | D14: 9 | E14: 8 | F14: =SUM(C14:E14) -> 25 | G14: =IFERROR($F14/$F$18,0) -> 0.091575092
A15: 11 | B15: Capacidad para ser Soportado | C15: 12 | D15: 13 | E15: 2 | F15: =SUM(C15:E15) -> 27 | G15: =IFERROR($F15/$F$18,0) -> 0.098901099
A16: 12 | B16: Portabilidad | C16: 4 | D16: 11 | E16: 13 | F16: =SUM(C16:E16) -> 28 | G16: =IFERROR($F16/$F$18,0) -> 0.1025641
A17: 13 | B17: Accesibilidad | C17: 7 | D17: 12 | E17: 11 | F17: =SUM(C17:E17) -> 30 | G17: =IFERROR($F17/$F$18,0) -> 0.10989011
B18: TOTAL | C18: =SUM(C5:C17) -> 91 | D18: =SUM(D5:D17) -> 91 | E18: =SUM(E5:E17) -> 91 | F18: =SUM(F5:F17) -> 273 | G18: =IFERROR($F18/$F18,0) -> 1
A20: Empates sin romper: Rendimiento y Capacidad para ser Auditado (17) · Experiencia de Usuario y Seguridad (24) · Interoperatividad y Escalabilidad (25).
A21: Seguridad de funcionamiento ya no aparece: quedó absorbida por Confiabilidad. Capacidad para ser Auditado sustituye a Trazabilidad y la amplía con cumplimiento.
A22: Confiabilidad es 1 para los tres actores: es el único consenso total del proyecto y por eso concentra 57 de las 262 preguntas.

Sheet Valores
A1: Respuesta | B1: Atributo
A2: Sí | B2: Confiabilidad
A3: No | B3: Disponibilidad
A4: N/A | B4: Rendimiento
B5: Capacidad para ser Auditado
B6: Capacidad
B7: Capacidad para ser Administrado
B8: Experiencia de Usuario
B9: Seguridad
B10: Interoperatividad
B11: Escalabilidad
B12: Capacidad para ser Soportado
B13: Portabilidad
B14: Accesibilidad
B15: Cierre de la sesión
